Workbook

Sheet 09-09
B1: 0.33333333 | D1: REPORTE DE ASISTENCIA 09 DE SEPTIEMBRE DEL 2026.
A2: Cargo | B2: Nombre | C2: Entrada | D2: Salida | E2: Llegada Tarde | F2: HORAS ACUMULADAS ENTRADA | G2: HORAS ACUMULADAS SALIDAS | H2: Total | I2: Observaciones
A3: Supervisor | B3: David Castillo Martínez | F3: =SUM(IF(C3="",0,IF(C3<TIME(8,0,0),TIME(8,0,0)-C3,0))) -> 0 | G3: =SUM( IF(OR(C3="",D3=""),0,MAX(0,IF(D3<C3,D3+1,D3)-MAX(C3,TIME(17,0,0))))) -> 0 | H3: =G3+F3 -> 0
A4: Admon. Bodega | B4: Lenin Amigo de Saul Mendoza Chavarria | F4: =SUM(IF(C4="",0,IF(C4<TIME(8,0,0),TIME(8,0,0)-C4,0))) -> 0 | G4: =SUM( IF(OR(C4="",D4=""),0,MAX(0,IF(D4<C4,D4+1,D4)-MAX(C4,TIME(17,0,0))))) -> 0 | H4: =G4+F4 -> 0
A5: Admon. Bodega | B5: Jose De Jesus Gaitan Lovo | F5: =SUM(IF(C5="",0,IF(C5<TIME(8,0,0),TIME(8,0,0)-C5,0))) -> 0 | G5: =SUM( IF(OR(C5="",D5=""),0,MAX(0,IF(D5<C5,D5+1,D5)-MAX(C5,TIME(17,0,0))))) -> 0 | H5: =G5+F5 -> 0
A6: Admon. Bodega | B6: Fernando Mauricio Salazar | F6: =SUM(IF(C6="",0,IF(C6<TIME(8,0,0),TIME(8,0,0)-C6,0))) -> 0 | G6: =SUM( IF(OR(C6="",D6=""),0,MAX(0,IF(D6<C6,D6+1,D6)-MAX(C6,TIME(17,0,0))))) -> 0 | H6: =G6+F6 -> 0
A7: Admon. Bodega | B7: Elvis Anthony Martinez Hernandez | F7: =SUM(IF(C7="",0,IF(C7<TIME(8,0,0),TIME(8,0,0)-C7,0))) -> 0 | G7: =SUM( IF(OR(C7="",D7=""),0,MAX(0,IF(D7<C7,D7+1,D7)-MAX(C7,TIME(17,0,0))))) -> 0 | H7: =G7+F7 -> 0
A8: Admon. Bodega | B8: Sebastian Bautista Rostran Davila | F8: =SUM(IF(C8="",0,IF(C8<TIME(8,0,0),TIME(8,0,0)-C8,0))) -> 0 | G8: =SUM( IF(OR(C8="",D8=""),0,MAX(0,IF(D8<C8,D8+1,D8)-MAX(C8,TIME(17,0,0))))) -> 0 | H8: =G8+F8 -> 0
A9: Conductor | B9: Denis Alberto Lopez Gonzaga | F9: =SUM(IF(C9="",0,IF(C9<TIME(8,0,0),TIME(8,0,0)-C9,0))) -> 0 | G9: =SUM( IF(OR(C9="",D9=""),0,MAX(0,IF(D9<C9,D9+1,D9)-MAX(C9,TIME(17,0,0))))) -> 0 | H9: =G9+F9 -> 0
A10: Conductor | B10: Jose Gabriel Herrera | F10: =SUM(IF(C10="",0,IF(C10<TIME(8,0,0),TIME(8,0,0)-C10,0))) -> 0 | G10: =SUM( IF(OR(C10="",D10=""),0,MAX(0,IF(D10<C10,D10+1,D10)-MAX(C10,TIME(17,0,0))))) -> 0 | H10: =G10+F10 -> 0
A11: Conductor | B11: Francisco Valerio Altamirano | F11: =SUM(IF(C11="",0,IF(C11<TIME(8,0,0),TIME(8,0,0)-C11,0))) -> 0 | G11: =SUM( IF(OR(C11="",D11=""),0,MAX(0,IF(D11<C11,D11+1,D11)-MAX(C11,TIME(17,0,0))))) -> 0 | H11: =G11+F11 -> 0
A12: Conductor | B12: Manuel Salvador Centeno Salinas | F12: =SUM(IF(C12="",0,IF(C12<TIME(8,0,0),TIME(8,0,0)-C12,0))) -> 0 | G12: =SUM( IF(OR(C12="",D12=""),0,MAX(0,IF(D12<C12,D12+1,D12)-MAX(C12,TIME(17,0,0))))) -> 0 | H12: =G12+F12 -> 0
A13: Conductor | B13: Bayardo Benjamin Moran Lopez | F13: =SUM(IF(C13="",0,IF(C13<TIME(8,0,0),TIME(8,0,0)-C13,0))) -> 0 | G13: =SUM( IF(OR(C13="",D13=""),0,MAX(0,IF(D13<C13,D13+1,D13)-MAX(C13,TIME(17,0,0))))) -> 0 | H13: =G13+F13 -> 0
A14: Conductor | B14: Emerson Alberto Diaz Mendoza | F14: =SUM(IF(C14="",0,IF(C14<TIME(8,0,0),TIME(8,0,0)-C14,0))) -> 0 | G14: =SUM( IF(OR(C14="",D14=""),0,MAX(0,IF(D14<C14,D14+1,D14)-MAX(C14,TIME(17,0,0))))) -> 0 | H14: =G14+F14 -> 0
... A63: Ayudante | B63: Guillermo José Reyes Fernández | F63: =SUM(IF(C63="",0,IF(C63<TIME(8,0,0),TIME(8,0,0)-C63,0))) -> 0 | G63: =SUM( IF(OR(C63="",D63=""),0,MAX(0,IF(D63<C63,D63+1,D63)-MAX(C63,TIME(17,0,0))))) -> 0 | H63: =G63+F63 -> 0
H64: =SUM(H3:H63) -> 0

Sheet MACHOTE
B1: 0.33333333 | D1: REPORTE DE ASISTENCIA 02 DE SEPTIEMBRE DEL 2026.
A2: Cargo | B2: Nombre | C2: Entrada | D2: Salida | E2: Llegada Tarde | F2: HORAS ACUMULADAS ENTRADA | G2: HORAS ACUMULADAS SALIDAS | H2: Total | I2: Observaciones
A3: Supervisor | B3: David Castillo Martínez | F3: =SUM(IF(C3="",0,IF(C3<TIME(8,0,0),TIME(8,0,0)-C3,0))) -> 0 | G3: =SUM( IF(OR(C3="",D3=""),0,MAX(0,IF(D3<C3,D3+1,D3)-MAX(C3,TIME(17,0,0))))) -> 0 | H3: =G3+F3 -> 0
A4: Admon. Bodega | B4: Lenin Amigo de Saul Mendoza Chavarria | F4: =SUM(IF(C4="",0,IF(C4<TIME(8,0,0),TIME(8,0,0)-C4,0))) -> 0 | G4: =SUM( IF(OR(C4="",D4=""),0,MAX(0,IF(D4<C4,D4+1,D4)-MAX(C4,TIME(17,0,0))))) -> 0 | H4: =G4+F4 -> 0
A5: Admon. Bodega | B5: Jose De Jesus Gaitan Lovo | F5: =SUM(IF(C5="",0,IF(C5<TIME(8,0,0),TIME(8,0,0)-C5,0))) -> 0 | G5: =SUM( IF(OR(C5="",D5=""),0,MAX(0,IF(D5<C5,D5+1,D5)-MAX(C5,TIME(17,0,0))))) -> 0 | H5: =G5+F5 -> 0
A6: Admon. Bodega | B6: Fernando Mauricio Salazar | F6: =SUM(IF(C6="",0,IF(C6<TIME(8,0,0),TIME(8,0,0)-C6,0))) -> 0 | G6: =SUM( IF(OR(C6="",D6=""),0,MAX(0,IF(D6<C6,D6+1,D6)-MAX(C6,TIME(17,0,0))))) -> 0 | H6: =G6+F6 -> 0
A7: Admon. Bodega | B7: Elvis Anthony Martinez Hernandez | F7: =SUM(IF(C7="",0,IF(C7<TIME(8,0,0),TIME(8,0,0)-C7,0))) -> 0 | G7: =SUM( IF(OR(C7="",D7=""),0,MAX(0,IF(D7<C7,D7+1,D7)-MAX(C7,TIME(17,0,0))))) -> 0 | H7: =G7+F7 -> 0
A8: Admon. Bodega | B8: Sebastian Bautista Rostran Davila | F8: =SUM(IF(C8="",0,IF(C8<TIME(8,0,0),TIME(8,0,0)-C8,0))) -> 0 | G8: =SUM( IF(OR(C8="",D8=""),0,MAX(0,IF(D8<C8,D8+1,D8)-MAX(C8,TIME(17,0,0))))) -> 0 | H8: =G8+F8 -> 0
A9: Conductor | B9: Denis Alberto Lopez Gonzaga | F9: =SUM(IF(C9="",0,IF(C9<TIME(8,0,0),TIME(8,0,0)-C9,0))) -> 0 | G9: =SUM( IF(OR(C9="",D9=""),0,MAX(0,IF(D9<C9,D9+1,D9)-MAX(C9,TIME(17,0,0))))) -> 0 | H9: =G9+F9 -> 0
A10: Conductor | B10: Jose Gabriel Herrera | F10: =SUM(IF(C10="",0,IF(C10<TIME(8,0,0),TIME(8,0,0)-C10,0))) -> 0 | G10: =SUM( IF(OR(C10="",D10=""),0,MAX(0,IF(D10<C10,D10+1,D10)-MAX(C10,TIME(17,0,0))))) -> 0 | H10: =G10+F10 -> 0
A11: Conductor | B11: Francisco Valerio Altamirano | F11: =SUM(IF(C11="",0,IF(C11<TIME(8,0,0),TIME(8,0,0)-C11,0))) -> 0 | G11: =SUM( IF(OR(C11="",D11=""),0,MAX(0,IF(D11<C11,D11+1,D11)-MAX(C11,TIME(17,0,0))))) -> 0 | H11: =G11+F11 -> 0
A12: Conductor | B12: Manuel Salvador Centeno Salinas | F12: =SUM(IF(C12="",0,IF(C12<TIME(8,0,0),TIME(8,0,0)-C12,0))) -> 0 | G12: =SUM( IF(OR(C12="",D12=""),0,MAX(0,IF(D12<C12,D12+1,D12)-MAX(C12,TIME(17,0,0))))) -> 0 | H12: =G12+F12 -> 0
A13: Conductor | B13: Bayardo Benjamin Moran Lopez | F13: =SUM(IF(C13="",0,IF(C13<TIME(8,0,0),TIME(8,0,0)-C13,0))) -> 0 | G13: =SUM( IF(OR(C13="",D13=""),0,MAX(0,IF(D13<C13,D13+1,D13)-MAX(C13,TIME(17,0,0))))) -> 0 | H13: =G13+F13 -> 0
A14: Conductor | B14: Emerson Alberto Diaz Mendoza | F14: =SUM(IF(C14="",0,IF(C14<TIME(8,0,0),TIME(8,0,0)-C14,0))) -> 0 | G14: =SUM( IF(OR(C14="",D14=""),0,MAX(0,IF(D14<C14,D14+1,D14)-MAX(C14,TIME(17,0,0))))) -> 0 | H14: =G14+F14 -> 0
... A63: Ayudante | B63: Guillermo José Reyes Fernández | F63: =SUM(IF(C63="",0,IF(C63<TIME(8,0,0),TIME(8,0,0)-C63,0))) -> 0 | G63: =SUM( IF(OR(C63="",D63=""),0,MAX(0,IF(D63<C63,D63+1,D63)-MAX(C63,TIME(17,0,0))))) -> 0 | H63: =G63+F63 -> 0
H64: =SUM(H3:H63) -> 0

Sheet 08-09
B1: 0.33333333 | D1: REPORTE DE ASISTENCIA 08 DE SEPTIEMBRE DEL 2026.
A2: Cargo | B2: Nombre | C2: Entrada | D2: Salida | E2: Llegada Tarde | F2: HORAS ACUMULADAS ENTRADA | G2: HORAS ACUMULADAS SALIDAS | H2: Total | I2: Observaciones
A3: Supervisor | B3: David Castillo Martínez | C3: SUBSIDIO
A4: Admon. Bodega | B4: Lenin Amigo de Saul Mendoza Chavarria | C4: 0.33333333 | D4: 0.79513889 | F4: =SUM(IF(C4="",0,IF(C4<TIME(8,0,0),TIME(8,0,0)-C4,0))) -> 0 | G4: =SUM( IF(OR(C4="",D4=""),0,MAX(0,IF(D4<C4,D4+1,D4)-MAX(C4,TIME(17,0,0))))) -> 0.086805556 | H4: =G4+F4 -> 0.086805556
A5: Admon. Bodega | B5: Jose De Jesus Gaitan Lovo | C5: 0.33333333 | D5: 0.79513889 | F5: =SUM(IF(C5="",0,IF(C5<TIME(8,0,0),TIME(8,0,0)-C5,0))) -> 0 | G5: =SUM( IF(OR(C5="",D5=""),0,MAX(0,IF(D5<C5,D5+1,D5)-MAX(C5,TIME(17,0,0))))) -> 0.086805556 | H5: =G5+F5 -> 0.086805556
A6: Admon. Bodega | B6: Fernando Mauricio Salazar | C6: 0.33333333 | D6: 0.79513889 | F6: =SUM(IF(C6="",0,IF(C6<TIME(8,0,0),TIME(8,0,0)-C6,0))) -> 0 | G6: =SUM( IF(OR(C6="",D6=""),0,MAX(0,IF(D6<C6,D6+1,D6)-MAX(C6,TIME(17,0,0))))) -> 0.086805556 | H6: =G6+F6 -> 0.086805556
A7: Admon. Bodega | B7: Elvis Anthony Martinez Hernandez | C7: 0.33333333 | D7: 0.70833333 | F7: =SUM(IF(C7="",0,IF(C7<TIME(8,0,0),TIME(8,0,0)-C7,0))) -> 0 | G7: =SUM( IF(OR(C7="",D7=""),0,MAX(0,IF(D7<C7,D7+1,D7)-MAX(C7,TIME(17,0,0))))) -> 0 | H7: =G7+F7 -> 0
A8: Conductor | B8: Denis Alberto Lopez Gonzaga | C8: 0.3125 | D8: 0.70833333 | F8: =SUM(IF(C8="",0,IF(C8<TIME(8,0,0),TIME(8,0,0)-C8,0))) -> 0.020833333 | G8: =SUM( IF(OR(C8="",D8=""),0,MAX(0,IF(D8<C8,D8+1,D8)-MAX(C8,TIME(17,0,0))))) -> 0 | H8: =G8+F8 -> 0.020833333
A9: Conductor | B9: Jose Gabriel Herrera | C9: 0.33333333 | D9: 0.70833333 | F9: =SUM(IF(C9="",0,IF(C9<TIME(8,0,0),TIME(8,0,0)-C9,0))) -> 0 | G9: =SUM( IF(OR(C9="",D9=""),0,MAX(0,IF(D9<C9,D9+1,D9)-MAX(C9,TIME(17,0,0))))) -> 0 | H9: =G9+F9 -> 0
A10: Conductor | B10: Francisco Valerio Altamirano | C10: A CUENTAS DE HORAS ACUMULADAS
A11: Conductor | B11: Manuel Salvador Centeno Salinas | C11: 0.33333333 | D11: 0.78125 | F11: =SUM(IF(C11="",0,IF(C11<TIME(8,0,0),TIME(8,0,0)-C11,0))) -> 0 | G11: =SUM( IF(OR(C11="",D11=""),0,MAX(0,IF(D11<C11,D11+1,D11)-MAX(C11,TIME(17,0,0))))) -> 0.072916667 | H11: =G11+F11 -> 0.072916667
A12: Conductor | B12: Bayardo Benjamin Moran Lopez | C12: 0.25 | D12: 0.80208333 | F12: =SUM(IF(C12="",0,IF(C12<TIME(8,0,0),TIME(8,0,0)-C12,0))) -> 0.083333333 | G12: =SUM( IF(OR(C12="",D12=""),0,MAX(0,IF(D12<C12,D12+1,D12)-MAX(C12,TIME(17,0,0))))) -> 0.09375 | H12: =G12+F12 -> 0.17708333
A13: Conductor | B13: Emerson Alberto Diaz Mendoza | C13: SUBSIDIO
A14: Conductor | B14: David Uriel Zamora Martinez | C14: 0.33333333 | D14: 0.70833333 | F14: =SUM(IF(C14="",0,IF(C14<TIME(8,0,0),TIME(8,0,0)-C14,0))) -> 0 | G14: =SUM( IF(OR(C14="",D14=""),0,MAX(0,IF(D14<C14,D14+1,D14)-MAX(C14,TIME(17,0,0))))) -> 0 | H14: =G14+F14 -> 0
A15: Conductor | B15: Jorge Luis Telleria | C15: 0.33333333 | D15: 0.70833333 | F15: =SUM(IF(C15="",0,IF(C15<TIME(8,0,0),TIME(8,0,0)-C15,0))) -> 0 | G15: =SUM( IF(OR(C15="",D15=""),0,MAX(0,IF(D15<C15,D15+1,D15)-MAX(C15,TIME(17,0,0))))) -> 0 | H15: =G15+F15 -> 0
A16: Conductor | B16: Alejandro Jose Castro Jarquin | C16: 0.33333333 | D16: 0.70833333 | F16: =SUM(IF(C16="",0,IF(C16<TIME(8,0,0),TIME(8,0,0)-C16,0))) -> 0 | G16: =SUM( IF(OR(C16="",D16=""),0,MAX(0,IF(D16<C16,D16+1,D16)-MAX(C16,TIME(17,0,0))))) -> 0 | H16: =G16+F16 -> 0
A17: Conductor | B17: Juan Francisco Narvaez Molina | C17: 0.33333333 | D17: 0.82222222 | F17: =SUM(IF(C17="",0,IF(C17<TIME(8,0,0),TIME(8,0,0)-C17,0))) -> 0 | G17: =SUM( IF(OR(C17="",D17=""),0,MAX(0,IF(D17<C17,D17+1,D17)-MAX(C17,TIME(17,0,0))))) -> 0.11388889 | H17: =G17+F17 -> 0.11388889
A18: Conductor | B18: Fernando Antonio Centeno Gaitan | C18: 0.33333333 | D18: 0.70833333 | F18: =SUM(IF(C18="",0,IF(C18<TIME(8,0,0),TIME(8,0,0)-C18,0))) -> 0 | G18: =SUM( IF(OR(C18="",D18=""),0,MAX(0,IF(D18<C18,D18+1,D18)-MAX(C18,TIME(17,0,0))))) -> 0 | H18: =G18+F18 -> 0
A19: Conductor | B19: Richard Antonio Carrion Alvarez | C19: 0.33333333 | D19: 0.71527778 | F19: =SUM(IF(C19="",0,IF(C19<TIME(8,0,0),TIME(8,0,0)-C19,0))) -> 0 | G19: =SUM( IF(OR(C19="",D19=""),0,MAX(0,IF(D19<C19,D19+1,D19)-MAX(C19,TIME(17,0,0))))) -> 0.0069444444 | H19: =G19+F19 -> 0.0069444444
A20: Conductor | B20: Dietrich Rafael Bone Burgos | C20: 0.33333333 | D20: 0.70833333 | F20: =SUM(IF(C20="",0,IF(C20<TIME(8,0,0),TIME(8,0,0)-C20,0))) -> 0 | G20: =SUM( IF(OR(C20="",D20=""),0,MAX(0,IF(D20<C20,D20+1,D20)-MAX(C20,TIME(17,0,0))))) -> 0 | H20: =G20+F20 -> 0
A21: Conductor | B21: Juan Abrahán Duran Tercero | C21: 0.29166667 | D21: 0.75277778 | F21: =SUM(IF(C21="",0,IF(C21<TIME(8,0,0),TIME(8,0,0)-C21,0))) -> 0.041666667 | G21: =SUM( IF(OR(C21="",D21=""),0,MAX(0,IF(D21<C21,D21+1,D21)-MAX(C21,TIME(17,0,0))))) -> 0.044444444 | H21: =G21+F21 -> 0.086111111
A22: Conductor | B22: Orlando José Ayerdis Barrios | C22: 0.33333333 | D22: 0.70833333 | F22: =SUM(IF(C22="",0,IF(C22<TIME(8,0,0),TIME(8,0,0)-C22,0))) -> 0 | G22: =SUM( IF(OR(C22="",D22=""),0,MAX(0,IF(D22<C22,D22+1,D22)-MAX(C22,TIME(17,0,0))))) -> 0 | H22: =G22+F22 -> 0
A23: Ayudante | B23: Walter Bernardino Aburto Maltez | C23: 0.42708333 | D23: 0.70833333 | F23: =SUM(IF(C23="",0,IF(C23<TIME(8,0,0),TIME(8,0,0)-C23,0))) -> 0 | G23: =SUM( IF(OR(C23="",D23=""),0,MAX(0,IF(D23<C23,D23+1,D23)-MAX(C23,TIME(17,0,0))))) -> 0 | H23: =G23+F23 -> 0 | I23: Constancia Medica
A24: Ayudante | B24: Bismarck Antonio Perez Aburto | C24: 0.33333333 | D24: 0.70833333 | F24: =SUM(IF(C24="",0,IF(C24<TIME(8,0,0),TIME(8,0,0)-C24,0))) -> 0 | G24: =SUM( IF(OR(C24="",D24=""),0,MAX(0,IF(D24<C24,D24+1,D24)-MAX(C24,TIME(17,0,0))))) -> 0 | H24: =G24+F24 -> 0
A25: Ayudante | B25: Jose Ariel Espinoza Parrales | C25: 0.3125 | D25: 0.70833333 | F25: =SUM(IF(C25="",0,IF(C25<TIME(8,0,0),TIME(8,0,0)-C25,0))) -> 0.020833333 | G25: =SUM( IF(OR(C25="",D25=""),0,MAX(0,IF(D25<C25,D25+1,D25)-MAX(C25,TIME(17,0,0))))) -> 0 | H25: =G25+F25 -> 0.020833333
A26: Ayudante | B26: Yaro de Jesus Castillo Muñoz | C26: 0.33333333 | D26: 0.70833333 | F26: =SUM(IF(C26="",0,IF(C26<TIME(8,0,0),TIME(8,0,0)-C26,0))) -> 0 | G26: =SUM( IF(OR(C26="",D26=""),0,MAX(0,IF(D26<C26,D26+1,D26)-MAX(C26,TIME(17,0,0))))) -> 0 | H26: =G26+F26 -> 0
A27: Ayudante | B27: Orlando De Jesus Ruiz Ramirez | C27: 0.33333333 | D27: 0.70833333 | F27: =SUM(IF(C27="",0,IF(C27<TIME(8,0,0),TIME(8,0,0)-C27,0))) -> 0 | G27: =SUM( IF(OR(C27="",D27=""),0,MAX(0,IF(D27<C27,D27+1,D27)-MAX(C27,TIME(17,0,0))))) -> 0 | H27: =G27+F27 -> 0
A28: Ayudante | B28: Roberto Jose Arauz Alvarado | C28: 0.33333333 | D28: 0.70833333 | F28: =SUM(IF(C28="",0,IF(C28<TIME(8,0,0),TIME(8,0,0)-C28,0))) -> 0 | G28: =SUM( IF(OR(C28="",D28=""),0,MAX(0,IF(D28<C28,D28+1,D28)-MAX(C28,TIME(17,0,0))))) -> 0 | H28: =G28+F28 -> 0
A29: Ayudante | B29: Luis Omar Campos Connolly | C29: 0.25 | D29: 0.80208333 | F29: =SUM(IF(C29="",0,IF(C29<TIME(8,0,0),TIME(8,0,0)-C29,0))) -> 0.083333333 | G29: =SUM( IF(OR(C29="",D29=""),0,MAX(0,IF(D29<C29,D29+1,D29)-MAX(C29,TIME(17,0,0))))) -> 0.09375 | H29: =G29+F29 -> 0.17708333
A30: Ayudante | B30: Emilio Humberto Alegria Sanchez | C30: SUBSIDIO
A31: Ayudante | B31: Pablo Javier Berrios Sotelo | C31: 0.33333333 | D31: 0.70833333 | F31: =SUM(IF(C31="",0,IF(C31<TIME(8,0,0),TIME(8,0,0)-C31,0))) -> 0 | G31: =SUM( IF(OR(C31="",D31=""),0,MAX(0,IF(D31<C31,D31+1,D31)-MAX(C31,TIME(17,0,0))))) -> 0 | H31: =G31+F31 -> 0
A32: Ayudante | B32: Ramiro Isaac Solano Flores | C32: 0.33333333 | D32: 0.70833333 | F32: =SUM(IF(C32="",0,IF(C32<TIME(8,0,0),TIME(8,0,0)-C32,0))) -> 0 | G32: =SUM( IF(OR(C32="",D32=""),0,MAX(0,IF(D32<C32,D32+1,D32)-MAX(C32,TIME(17,0,0))))) -> 0 | H32: =G32+F32 -> 0
A33: Ayudante | B33: Reggie Sanders Rodriguez Tellez | C33: A CUENTAS DE HORAS ACUMULADAS
A34: Ayudante | B34: Engel Jose Brenes Aleman | C34: 0.33333333 | D34: 0.70833333 | F34: =SUM(IF(C34="",0,IF(C34<TIME(8,0,0),TIME(8,0,0)-C34,0))) -> 0 | G34: =SUM( IF(OR(C34="",D34=""),0,MAX(0,IF(D34<C34,D34+1,D34)-MAX(C34,TIME(17,0,0))))) -> 0 | H34: =G34+F34 -> 0
A35: Ayudante | B35: Ricky Nelson Bonilla Villagra | C35: 0.33333333 | D35: 0.70833333 | F35: =SUM(IF(C35="",0,IF(C35<TIME(8,0,0),TIME(8,0,0)-C35,0))) -> 0 | G35: =SUM( IF(OR(C35="",D35=""),0,MAX(0,IF(D35<C35,D35+1,D35)-MAX(C35,TIME(17,0,0))))) -> 0 | H35: =G35+F35 -> 0
A36: Ayudante | B36: Diego Manuel Potoy Vanegas | C36: 0.33333333 | D36: 0.70833333 | F36: =SUM(IF(C36="",0,IF(C36<TIME(8,0,0),TIME(8,0,0)-C36,0))) -> 0 | G36: =SUM( IF(OR(C36="",D36=""),0,MAX(0,IF(D36<C36,D36+1,D36)-MAX(C36,TIME(17,0,0))))) -> 0 | H36: =G36+F36 -> 0
A37: Ayudante | B37: Henry Alberto Arevalo Velasquez | C37: 0.33333333 | D37: 0.70833333 | F37: =SUM(IF(C37="",0,IF(C37<TIME(8,0,0),TIME(8,0,0)-C37,0))) -> 0 | G37: =SUM( IF(OR(C37="",D37=""),0,MAX(0,IF(D37<C37,D37+1,D37)-MAX(C37,TIME(17,0,0))))) -> 0 | H37: =G37+F37 -> 0
A38: Ayudante | B38: Magdiel Daniel Cruz Aleman | C38: 0.33333333 | D38: 0.70833333 | F38: =SUM(IF(C38="",0,IF(C38<TIME(8,0,0),TIME(8,0,0)-C38,0))) -> 0 | G38: =SUM( IF(OR(C38="",D38=""),0,MAX(0,IF(D38<C38,D38+1,D38)-MAX(C38,TIME(17,0,0))))) -> 0 | H38: =G38+F38 -> 0
A39: Ayudante | B39: Carlos Jose Villavicencio Silva | C39: 0.33333333 | D39: 0.70833333 | F39: =SUM(IF(C39="",0,IF(C39<TIME(8,0,0),TIME(8,0,0)-C39,0))) -> 0 | G39: =SUM( IF(OR(C39="",D39=""),0,MAX(0,IF(D39<C39,D39+1,D39)-MAX(C39,TIME(17,0,0))))) -> 0 | H39: =G39+F39 -> 0
A40: Ayudante | B40: Einer Eliasar Lopez Hernandez | C40: 0.26388889 | D40: 0.6875 | F40: =SUM(IF(C40="",0,IF(C40<TIME(8,0,0),TIME(8,0,0)-C40,0))) -> 0.069444444 | G40: =SUM( IF(OR(C40="",D40=""),0,MAX(0,IF(D40<C40,D40+1,D40)-MAX(C40,TIME(17,0,0))))) -> 0 | H40: =G40+F40 -> 0.069444444 | I40: DEDUCIDO POR HORAS ACUMULADAS
...

Sheet 07-09
B1: 0.33333333 | D1: REPORTE DE ASISTENCIA 07 DE SEPTIEMBRE DEL 2026.
A2: Cargo | B2: Nombre | C2: Entrada | D2: Salida | E2: Llegada Tarde | F2: HORAS ACUMULADAS ENTRADA | G2: HORAS ACUMULADAS SALIDAS | H2: Total | I2: Observaciones
A3: Supervisor | B3: David Castillo Martínez | C3: SUBSIDIO
A4: Admon. Bodega | B4: Lenin Amigo de Saul Mendoza Chavarria | C4: 0.33333333 | D4: 0.70833333 | F4: =SUM(IF(C4="",0,IF(C4<TIME(8,0,0),TIME(8,0,0)-C4,0))) -> 0 | G4: =SUM( IF(OR(C4="",D4=""),0,MAX(0,IF(D4<C4,D4+1,D4)-MAX(C4,TIME(17,0,0))))) -> 0 | H4: =G4+F4 -> 0
A5: Admon. Bodega | B5: Jose De Jesus Gaitan Lovo | C5: 0.33333333 | D5: 0.70833333 | F5: =SUM(IF(C5="",0,IF(C5<TIME(8,0,0),TIME(8,0,0)-C5,0))) -> 0 | G5: =SUM( IF(OR(C5="",D5=""),0,MAX(0,IF(D5<C5,D5+1,D5)-MAX(C5,TIME(17,0,0))))) -> 0 | H5: =G5+F5 -> 0
A6: Admon. Bodega | B6: Fernando Mauricio Salazar | C6: 0.38402778 | D6: 0.70833333 | F6: =SUM(IF(C6="",0,IF(C6<TIME(8,0,0),TIME(8,0,0)-C6,0))) -> 0 | G6: =SUM( IF(OR(C6="",D6=""),0,MAX(0,IF(D6<C6,D6+1,D6)-MAX(C6,TIME(17,0,0))))) -> 0 | H6: =G6+F6 -> 0 | I6: DEDUCIDO POR HORAS ACUMULADAS
A7: Admon. Bodega | B7: Elvis Anthony Martinez Hernandez | C7: 0.33333333 | D7: 0.70833333 | F7: =SUM(IF(C7="",0,IF(C7<TIME(8,0,0),TIME(8,0,0)-C7,0))) -> 0 | G7: =SUM( IF(OR(C7="",D7=""),0,MAX(0,IF(D7<C7,D7+1,D7)-MAX(C7,TIME(17,0,0))))) -> 0 | H7: =G7+F7 -> 0
A8: Conductor | B8: Denis Alberto Lopez Gonzaga | C8: 0.33333333 | D8: 0.70833333 | F8: =SUM(IF(C8="",0,IF(C8<TIME(8,0,0),TIME(8,0,0)-C8,0))) -> 0 | G8: =SUM( IF(OR(C8="",D8=""),0,MAX(0,IF(D8<C8,D8+1,D8)-MAX(C8,TIME(17,0,0))))) -> 0 | H8: =G8+F8 -> 0
A9: Conductor | B9: Jose Gabriel Herrera | C9: 0.33333333 | D9: 0.70833333 | F9: =SUM(IF(C9="",0,IF(C9<TIME(8,0,0),TIME(8,0,0)-C9,0))) -> 0 | G9: =SUM( IF(OR(C9="",D9=""),0,MAX(0,IF(D9<C9,D9+1,D9)-MAX(C9,TIME(17,0,0))))) -> 0 | H9: =G9+F9 -> 0
A10: Conductor | B10: Francisco Valerio Altamirano | C10: A CUENTAS DE HORAS ACUMULADAS
A11: Conductor | B11: Manuel Salvador Centeno Salinas | C11: 0.29166667 | D11: 0.70833333 | F11: =SUM(IF(C11="",0,IF(C11<TIME(8,0,0),TIME(8,0,0)-C11,0))) -> 0.041666667 | G11: =SUM( IF(OR(C11="",D11=""),0,MAX(0,IF(D11<C11,D11+1,D11)-MAX(C11,TIME(17,0,0))))) -> 0 | H11: =G11+F11 -> 0.041666667
A12: Conductor | B12: Bayardo Benjamin Moran Lopez | C12: 0.33333333 | D12: 0.70833333 | F12: =SUM(IF(C12="",0,IF(C12<TIME(8,0,0),TIME(8,0,0)-C12,0))) -> 0 | G12: =SUM( IF(OR(C12="",D12=""),0,MAX(0,IF(D12<C12,D12+1,D12)-MAX(C12,TIME(17,0,0))))) -> 0 | H12: =G12+F12 -> 0
A13: Conductor | B13: Emerson Alberto Diaz Mendoza | C13: SUBSIDIO
A14: Conductor | B14: David Uriel Zamora Martinez | C14: 0.33333333 | D14: 0.70833333 | F14: =SUM(IF(C14="",0,IF(C14<TIME(8,0,0),TIME(8,0,0)-C14,0))) -> 0 | G14: =SUM( IF(OR(C14="",D14=""),0,MAX(0,IF(D14<C14,D14+1,D14)-MAX(C14,TIME(17,0,0))))) -> 0 | H14: =G14+F14 -> 0
A15: Conductor | B15: Jorge Luis Telleria | C15: 0.26388889 | D15: 0.70833333 | F15: =SUM(IF(C15="",0,IF(C15<TIME(8,0,0),TIME(8,0,0)-C15,0))) -> 0.069444444 | G15: =SUM( IF(OR(C15="",D15=""),0,MAX(0,IF(D15<C15,D15+1,D15)-MAX(C15,TIME(17,0,0))))) -> 0 | H15: =G15+F15 -> 0.069444444
A16: Conductor | B16: Alejandro Jose Castro Jarquin | C16: 0.33333333 | D16: 0.70833333 | F16: =SUM(IF(C16="",0,IF(C16<TIME(8,0,0),TIME(8,0,0)-C16,0))) -> 0 | G16: =SUM( IF(OR(C16="",D16=""),0,MAX(0,IF(D16<C16,D16+1,D16)-MAX(C16,TIME(17,0,0))))) -> 0 | H16: =G16+F16 -> 0
A17: Conductor | B17: Juan Francisco Narvaez Molina | C17: 0.33333333 | D17: 0.70833333 | F17: =SUM(IF(C17="",0,IF(C17<TIME(8,0,0),TIME(8,0,0)-C17,0))) -> 0 | G17: =SUM( IF(OR(C17="",D17=""),0,MAX(0,IF(D17<C17,D17+1,D17)-MAX(C17,TIME(17,0,0))))) -> 0 | H17: =G17+F17 -> 0
A18: Conductor | B18: Fernando Antonio Centeno Gaitan | C18: A CUENTAS DE HORAS ACUMULADAS
A19: Conductor | B19: Richard Antonio Carrion Alvarez | C19: 0.33333333 | D19: 0.70833333 | F19: =SUM(IF(C19="",0,IF(C19<TIME(8,0,0),TIME(8,0,0)-C19,0))) -> 0 | G19: =SUM( IF(OR(C19="",D19=""),0,MAX(0,IF(D19<C19,D19+1,D19)-MAX(C19,TIME(17,0,0))))) -> 0 | H19: =G19+F19 -> 0
A20: Conductor | B20: Dietrich Rafael Bone Burgos | C20: VACACIONES
A21: Conductor | B21: Juan Abrahán Duran Tercero | C21: 0.33333333 | D21: 0.70833333 | F21: =SUM(IF(C21="",0,IF(C21<TIME(8,0,0),TIME(8,0,0)-C21,0))) -> 0 | G21: =SUM( IF(OR(C21="",D21=""),0,MAX(0,IF(D21<C21,D21+1,D21)-MAX(C21,TIME(17,0,0))))) -> 0 | H21: =G21+F21 -> 0
A22: Conductor | B22: Orlando José Ayerdis Barrios | C22: 0.33333333 | D22: 0.70833333 | F22: =SUM(IF(C22="",0,IF(C22<TIME(8,0,0),TIME(8,0,0)-C22,0))) -> 0 | G22: =SUM( IF(OR(C22="",D22=""),0,MAX(0,IF(D22<C22,D22+1,D22)-MAX(C22,TIME(17,0,0))))) -> 0 | H22: =G22+F22 -> 0
A23: Ayudante | B23: Walter Bernardino Aburto Maltez | C23: 0.33333333 | D23: 0.70833333 | F23: =SUM(IF(C23="",0,IF(C23<TIME(8,0,0),TIME(8,0,0)-C23,0))) -> 0 | G23: =SUM( IF(OR(C23="",D23=""),0,MAX(0,IF(D23<C23,D23+1,D23)-MAX(C23,TIME(17,0,0))))) -> 0 | H23: =G23+F23 -> 0
A24: Ayudante | B24: Bismarck Antonio Perez Aburto | C24: 0.33333333 | D24: 0.70833333 | F24: =SUM(IF(C24="",0,IF(C24<TIME(8,0,0),TIME(8,0,0)-C24,0))) -> 0 | G24: =SUM( IF(OR(C24="",D24=""),0,MAX(0,IF(D24<C24,D24+1,D24)-MAX(C24,TIME(17,0,0))))) -> 0 | H24: =G24+F24 -> 0
A25: Ayudante | B25: Jose Ariel Espinoza Parrales | C25: 0.33333333 | D25: 0.70833333 | F25: =SUM(IF(C25="",0,IF(C25<TIME(8,0,0),TIME(8,0,0)-C25,0))) -> 0 | G25: =SUM( IF(OR(C25="",D25=""),0,MAX(0,IF(D25<C25,D25+1,D25)-MAX(C25,TIME(17,0,0))))) -> 0 | H25: =G25+F25 -> 0
A26: Ayudante | B26: Yaro de Jesus Castillo Muñoz | C26: 0.33333333 | D26: 0.70833333 | F26: =SUM(IF(C26="",0,IF(C26<TIME(8,0,0),TIME(8,0,0)-C26,0))) -> 0 | G26: =SUM( IF(OR(C26="",D26=""),0,MAX(0,IF(D26<C26,D26+1,D26)-MAX(C26,TIME(17,0,0))))) -> 0 | H26: =G26+F26 -> 0
A27: Ayudante | B27: Orlando De Jesus Ruiz Ramirez | C27: 0.33333333 | D27: 0.70833333 | F27: =SUM(IF(C27="",0,IF(C27<TIME(8,0,0),TIME(8,0,0)-C27,0))) -> 0 | G27: =SUM( IF(OR(C27="",D27=""),0,MAX(0,IF(D27<C27,D27+1,D27)-MAX(C27,TIME(17,0,0))))) -> 0 | H27: =G27+F27 -> 0
A28: Ayudante | B28: Roberto Jose Arauz Alvarado | C28: 0.33333333 | D28: 0.70833333 | F28: =SUM(IF(C28="",0,IF(C28<TIME(8,0,0),TIME(8,0,0)-C28,0))) -> 0 | G28: =SUM( IF(OR(C28="",D28=""),0,MAX(0,IF(D28<C28,D28+1,D28)-MAX(C28,TIME(17,0,0))))) -> 0 | H28: =G28+F28 -> 0
A29: Ayudante | B29: Luis Omar Campos Connolly | C29: 0.26388889 | D29: 0.70833333 | F29: =SUM(IF(C29="",0,IF(C29<TIME(8,0,0),TIME(8,0,0)-C29,0))) -> 0.069444444 | G29: =SUM( IF(OR(C29="",D29=""),0,MAX(0,IF(D29<C29,D29+1,D29)-MAX(C29,TIME(17,0,0))))) -> 0 | H29: =G29+F29 -> 0.069444444
A30: Ayudante | B30: Emilio Humberto Alegria Sanchez | C30: SUBSIDIO
A31: Ayudante | B31: Pablo Javier Berrios Sotelo | C31: 0.33333333 | D31: 0.70833333 | F31: =SUM(IF(C31="",0,IF(C31<TIME(8,0,0),TIME(8,0,0)-C31,0))) -> 0 | G31: =SUM( IF(OR(C31="",D31=""),0,MAX(0,IF(D31<C31,D31+1,D31)-MAX(C31,TIME(17,0,0))))) -> 0 | H31: =G31+F31 -> 0
A32: Ayudante | B32: Ramiro Isaac Solano Flores | C32: 0.33333333 | D32: 0.70833333 | F32: =SUM(IF(C32="",0,IF(C32<TIME(8,0,0),TIME(8,0,0)-C32,0))) -> 0 | G32: =SUM( IF(OR(C32="",D32=""),0,MAX(0,IF(D32<C32,D32+1,D32)-MAX(C32,TIME(17,0,0))))) -> 0 | H32: =G32+F32 -> 0
A33: Ayudante | B33: Reggie Sanders Rodriguez Tellez | C33: A CUENTAS DE HORAS ACUMULADAS
A34: Ayudante | B34: Engel Jose Brenes Aleman | C34: 0.33333333 | D34: 0.70833333 | F34: =SUM(IF(C34="",0,IF(C34<TIME(8,0,0),TIME(8,0,0)-C34,0))) -> 0 | G34: =SUM( IF(OR(C34="",D34=""),0,MAX(0,IF(D34<C34,D34+1,D34)-MAX(C34,TIME(17,0,0))))) -> 0 | H34: =G34+F34 -> 0
A35: Ayudante | B35: Ricky Nelson Bonilla Villagra | C35: 0.33333333 | D35: 0.70833333 | F35: =SUM(IF(C35="",0,IF(C35<TIME(8,0,0),TIME(8,0,0)-C35,0))) -> 0 | G35: =SUM( IF(OR(C35="",D35=""),0,MAX(0,IF(D35<C35,D35+1,D35)-MAX(C35,TIME(17,0,0))))) -> 0 | H35: =G35+F35 -> 0
A36: Ayudante | B36: Diego Manuel Potoy Vanegas | C36: 0.33333333 | D36: 0.70833333 | F36: =SUM(IF(C36="",0,IF(C36<TIME(8,0,0),TIME(8,0,0)-C36,0))) -> 0 | G36: =SUM( IF(OR(C36="",D36=""),0,MAX(0,IF(D36<C36,D36+1,D36)-MAX(C36,TIME(17,0,0))))) -> 0 | H36: =G36+F36 -> 0
A37: Ayudante | B37: Henry Alberto Arevalo Velasquez | C37: 0.33333333 | D37: 0.70833333 | F37: =SUM(IF(C37="",0,IF(C37<TIME(8,0,0),TIME(8,0,0)-C37,0))) -> 0 | G37: =SUM( IF(OR(C37="",D37=""),0,MAX(0,IF(D37<C37,D37+1,D37)-MAX(C37,TIME(17,0,0))))) -> 0 | H37: =G37+F37 -> 0
A38: Ayudante | B38: Magdiel Daniel Cruz Aleman | C38: 0.33333333 | D38: 0.70833333 | F38: =SUM(IF(C38="",0,IF(C38<TIME(8,0,0),TIME(8,0,0)-C38,0))) -> 0 | G38: =SUM( IF(OR(C38="",D38=""),0,MAX(0,IF(D38<C38,D38+1,D38)-MAX(C38,TIME(17,0,0))))) -> 0 | H38: =G38+F38 -> 0
A39: Ayudante | B39: Carlos Jose Villavicencio Silva | C39: 0.33333333 | D39: 0.70833333 | F39: =SUM(IF(C39="",0,IF(C39<TIME(8,0,0),TIME(8,0,0)-C39,0))) -> 0 | G39: =SUM( IF(OR(C39="",D39=""),0,MAX(0,IF(D39<C39,D39+1,D39)-MAX(C39,TIME(17,0,0))))) -> 0 | H39: =G39+F39 -> 0
A40: Ayudante | B40: Einer Eliasar Lopez Hernandez | C40: 0.33333333 | D40: 0.70833333 | F40: =SUM(IF(C40="",0,IF(C40<TIME(8,0,0),TIME(8,0,0)-C40,0))) -> 0 | G40: =SUM( IF(OR(C40="",D40=""),0,MAX(0,IF(D40<C40,D40+1,D40)-MAX(C40,TIME(17,0,0))))) -> 0 | H40: =G40+F40 -> 0
...

Sheet 05-09
B1: 0.33333333 | D1: REPORTE DE ASISTENCIA 05 DE SEPTIEMBRE DEL 2026.
A2: Cargo | B2: Nombre | C2: Entrada | D2: Salida | E2: Llegada Tarde | F2: HORAS ACUMULADAS ENTRADA | G2: HORAS ACUMULADAS SALIDAS | H2: Total | I2: Observaciones
A3: Supervisor | B3: David Castillo Martínez | C3: SUBSIDIO
A4: Admon. Bodega | B4: Lenin Amigo de Saul Mendoza Chavarria | C4: 0.33333333 | D4: 0.5625 | F4: =SUM(IF(C4="",0,IF(C4<TIME(8,0,0),TIME(8,0,0)-C4,0))) -> 0 | G4: =SUM( IF(OR(C4="",D4=""),0,MAX(0,IF(D4<C4,D4+1,D4)-MAX(C4,TIME(12,0,0))))) -> 0.0625 | H4: =G4+F4 -> 0.0625
A5: Admon. Bodega | B5: Jose De Jesus Gaitan Lovo | C5: 0.33333333 | D5: 0.5625 | F5: =SUM(IF(C5="",0,IF(C5<TIME(8,0,0),TIME(8,0,0)-C5,0))) -> 0 | G5: =SUM( IF(OR(C5="",D5=""),0,MAX(0,IF(D5<C5,D5+1,D5)-MAX(C5,TIME(12,0,0))))) -> 0.0625 | H5: =G5+F5 -> 0.0625
A6: Admon. Bodega | B6: Fernando Mauricio Salazar | C6: 0.33333333 | D6: 0.5625 | F6: =SUM(IF(C6="",0,IF(C6<TIME(8,0,0),TIME(8,0,0)-C6,0))) -> 0 | G6: =SUM( IF(OR(C6="",D6=""),0,MAX(0,IF(D6<C6,D6+1,D6)-MAX(C6,TIME(12,0,0))))) -> 0.0625 | H6: =G6+F6 -> 0.0625
A7: Admon. Bodega | B7: Elvis Anthony Martinez Hernandez | C7: 0.33333333 | D7: 0.5625 | F7: =SUM(IF(C7="",0,IF(C7<TIME(8,0,0),TIME(8,0,0)-C7,0))) -> 0 | G7: =SUM( IF(OR(C7="",D7=""),0,MAX(0,IF(D7<C7,D7+1,D7)-MAX(C7,TIME(12,0,0))))) -> 0.0625 | H7: =G7+F7 -> 0.0625
A8: Conductor | B8: Denis Alberto Lopez Gonzaga | C8: 0.33333333 | D8: 0.57152778 | F8: =SUM(IF(C8="",0,IF(C8<TIME(8,0,0),TIME(8,0,0)-C8,0))) -> 0 | G8: =SUM( IF(OR(C8="",D8=""),0,MAX(0,IF(D8<C8,D8+1,D8)-MAX(C8,TIME(12,0,0))))) -> 0.071527778 | H8: =G8+F8 -> 0.071527778
A9: Conductor | B9: Jose Gabriel Herrera | C9: 0.33333333 | D9: 0.52083333 | F9: =SUM(IF(C9="",0,IF(C9<TIME(8,0,0),TIME(8,0,0)-C9,0))) -> 0 | G9: =SUM( IF(OR(C9="",D9=""),0,MAX(0,IF(D9<C9,D9+1,D9)-MAX(C9,TIME(12,0,0))))) -> 0.020833333 | H9: =G9+F9 -> 0.020833333
A10: Conductor | B10: Francisco Valerio Altamirano | C10: 0.33333333 | D10: 0.57638889 | F10: =SUM(IF(C10="",0,IF(C10<TIME(8,0,0),TIME(8,0,0)-C10,0))) -> 0 | G10: =SUM( IF(OR(C10="",D10=""),0,MAX(0,IF(D10<C10,D10+1,D10)-MAX(C10,TIME(12,0,0))))) -> 0.076388889 | H10: =G10+F10 -> 0.076388889
A11: Conductor | B11: Manuel Salvador Centeno Salinas | C11: 0.33333333 | D11: 0.52083333 | F11: =SUM(IF(C11="",0,IF(C11<TIME(8,0,0),TIME(8,0,0)-C11,0))) -> 0 | G11: =SUM( IF(OR(C11="",D11=""),0,MAX(0,IF(D11<C11,D11+1,D11)-MAX(C11,TIME(12,0,0))))) -> 0.020833333 | H11: =G11+F11 -> 0.020833333
A12: Conductor | B12: Bayardo Benjamin Moran Lopez | C12: 0.33333333 | D12: 0.5 | F12: =SUM(IF(C12="",0,IF(C12<TIME(8,0,0),TIME(8,0,0)-C12,0))) -> 0 | G12: =SUM( IF(OR(C12="",D12=""),0,MAX(0,IF(D12<C12,D12+1,D12)-MAX(C12,TIME(12,0,0))))) -> 0 | H12: =G12+F12 -> 0
A13: Conductor | B13: Emerson Alberto Diaz Mendoza | C13: SUBSIDIO
A14: Conductor | B14: David Uriel Zamora Martinez | C14: 0.33333333 | D14: 0.52083333 | F14: =SUM(IF(C14="",0,IF(C14<TIME(8,0,0),TIME(8,0,0)-C14,0))) -> 0 | G14: =SUM( IF(OR(C14="",D14=""),0,MAX(0,IF(D14<C14,D14+1,D14)-MAX(C14,TIME(12,0,0))))) -> 0.020833333 | H14: =G14+F14 -> 0.020833333
A15: Conductor | B15: Jorge Luis Telleria | C15: 0.33333333 | D15: 0.5625 | F15: =SUM(IF(C15="",0,IF(C15<TIME(8,0,0),TIME(8,0,0)-C15,0))) -> 0 | G15: =SUM( IF(OR(C15="",D15=""),0,MAX(0,IF(D15<C15,D15+1,D15)-MAX(C15,TIME(12,0,0))))) -> 0.0625 | H15: =G15+F15 -> 0.0625
A16: Conductor | B16: Alejandro Jose Castro Jarquin | C16: 0.33333333 | D16: 0.52083333 | F16: =SUM(IF(C16="",0,IF(C16<TIME(8,0,0),TIME(8,0,0)-C16,0))) -> 0 | G16: =SUM( IF(OR(C16="",D16=""),0,MAX(0,IF(D16<C16,D16+1,D16)-MAX(C16,TIME(12,0,0))))) -> 0.020833333 | H16: =G16+F16 -> 0.020833333
A17: Conductor | B17: Juan Francisco Narvaez Molina | C17: 0.33333333 | D17: 0.52083333 | F17: =SUM(IF(C17="",0,IF(C17<TIME(8,0,0),TIME(8,0,0)-C17,0))) -> 0 | G17: =SUM( IF(OR(C17="",D17=""),0,MAX(0,IF(D17<C17,D17+1,D17)-MAX(C17,TIME(12,0,0))))) -> 0.020833333 | H17: =G17+F17 -> 0.020833333
A18: Conductor | B18: Fernando Antonio Centeno Gaitan | C18: 0.33333333 | D18: 0.52083333 | F18: =SUM(IF(C18="",0,IF(C18<TIME(8,0,0),TIME(8,0,0)-C18,0))) -> 0 | G18: =SUM( IF(OR(C18="",D18=""),0,MAX(0,IF(D18<C18,D18+1,D18)-MAX(C18,TIME(12,0,0))))) -> 0.020833333 | H18: =G18+F18 -> 0.020833333
A19: Conductor | B19: Richard Antonio Carrion Alvarez | C19: VACACIONES
A20: Conductor | B20: Dietrich Rafael Bone Burgos | C20: VACACIONES
A21: Conductor | B21: Juan Abrahán Duran Tercero | C21: 0.33333333 | D21: 0.52083333 | F21: =SUM(IF(C21="",0,IF(C21<TIME(8,0,0),TIME(8,0,0)-C21,0))) -> 0 | G21: =SUM( IF(OR(C21="",D21=""),0,MAX(0,IF(D21<C21,D21+1,D21)-MAX(C21,TIME(12,0,0))))) -> 0.020833333 | H21: =G21+F21 -> 0.020833333
A22: Conductor | B22: Orlando José Ayerdis Barrios | C22: 0.33333333 | D22: 0.52083333 | F22: =SUM(IF(C22="",0,IF(C22<TIME(8,0,0),TIME(8,0,0)-C22,0))) -> 0 | G22: =SUM( IF(OR(C22="",D22=""),0,MAX(0,IF(D22<C22,D22+1,D22)-MAX(C22,TIME(12,0,0))))) -> 0.020833333 | H22: =G22+F22 -> 0.020833333
A23: Ayudante | B23: Walter Bernardino Aburto Maltez | C23: VACACIONES
A24: Ayudante | B24: Bismarck Antonio Perez Aburto | C24: 0.33333333 | D24: 0.52083333 | F24: =SUM(IF(C24="",0,IF(C24<TIME(8,0,0),TIME(8,0,0)-C24,0))) -> 0 | G24: =SUM( IF(OR(C24="",D24=""),0,MAX(0,IF(D24<C24,D24+1,D24)-MAX(C24,TIME(12,0,0))))) -> 0.020833333 | H24: =G24+F24 -> 0.020833333
A25: Ayudante | B25: Jose Ariel Espinoza Parrales | C25: 0.33333333 | D25: 0.52083333 | F25: =SUM(IF(C25="",0,IF(C25<TIME(8,0,0),TIME(8,0,0)-C25,0))) -> 0 | G25: =SUM( IF(OR(C25="",D25=""),0,MAX(0,IF(D25<C25,D25+1,D25)-MAX(C25,TIME(12,0,0))))) -> 0.020833333 | H25: =G25+F25 -> 0.020833333
A26: Ayudante | B26: Yaro de Jesus Castillo Muñoz | C26: 0.33333333 | D26: 0.52083333 | F26: =SUM(IF(C26="",0,IF(C26<TIME(8,0,0),TIME(8,0,0)-C26,0))) -> 0 | G26: =SUM( IF(OR(C26="",D26=""),0,MAX(0,IF(D26<C26,D26+1,D26)-MAX(C26,TIME(12,0,0))))) -> 0.020833333 | H26: =G26+F26 -> 0.020833333
A27: Ayudante | B27: Orlando De Jesus Ruiz Ramirez | C27: 0.33333333 | D27: 0.5625 | F27: =SUM(IF(C27="",0,IF(C27<TIME(8,0,0),TIME(8,0,0)-C27,0))) -> 0 | G27: =SUM( IF(OR(C27="",D27=""),0,MAX(0,IF(D27<C27,D27+1,D27)-MAX(C27,TIME(12,0,0))))) -> 0.0625 | H27: =G27+F27 -> 0.0625
A28: Ayudante | B28: Roberto Jose Arauz Alvarado | C28: 0.33333333 | D28: 0.5625 | F28: =SUM(IF(C28="",0,IF(C28<TIME(8,0,0),TIME(8,0,0)-C28,0))) -> 0 | G28: =SUM( IF(OR(C28="",D28=""),0,MAX(0,IF(D28<C28,D28+1,D28)-MAX(C28,TIME(12,0,0))))) -> 0.0625 | H28: =G28+F28 -> 0.0625
A29: Ayudante | B29: Luis Omar Campos Connolly | C29: 0.33333333 | D29: 0.5 | F29: =SUM(IF(C29="",0,IF(C29<TIME(8,0,0),TIME(8,0,0)-C29,0))) -> 0 | G29: =SUM( IF(OR(C29="",D29=""),0,MAX(0,IF(D29<C29,D29+1,D29)-MAX(C29,TIME(12,0,0))))) -> 0 | H29: =G29+F29 -> 0
A30: Ayudante | B30: Emilio Humberto Alegria Sanchez | C30: SUBSIDIO
A31: Ayudante | B31: Pablo Javier Berrios Sotelo | C31: 0.33333333 | D31: 0.52083333 | F31: =SUM(IF(C31="",0,IF(C31<TIME(8,0,0),TIME(8,0,0)-C31,0))) -> 0 | G31: =SUM( IF(OR(C31="",D31=""),0,MAX(0,IF(D31<C31,D31+1,D31)-MAX(C31,TIME(12,0,0))))) -> 0.020833333 | H31: =G31+F31 -> 0.020833333
A32: Ayudante | B32: Ramiro Isaac Solano Flores | C32: 0.33333333 | D32: 0.52083333 | F32: =SUM(IF(C32="",0,IF(C32<TIME(8,0,0),TIME(8,0,0)-C32,0))) -> 0 | G32: =SUM( IF(OR(C32="",D32=""),0,MAX(0,IF(D32<C32,D32+1,D32)-MAX(C32,TIME(12,0,0))))) -> 0.020833333 | H32: =G32+F32 -> 0.020833333
A33: Ayudante | B33: Reggie Sanders Rodriguez Tellez | C33: 0.33333333 | D33: 0.5 | F33: =SUM(IF(C33="",0,IF(C33<TIME(8,0,0),TIME(8,0,0)-C33,0))) -> 0 | G33: =SUM( IF(OR(C33="",D33=""),0,MAX(0,IF(D33<C33,D33+1,D33)-MAX(C33,TIME(12,0,0))))) -> 0 | H33: =G33+F33 -> 0
A34: Ayudante | B34: Engel Jose Brenes Aleman | C34: 0.33333333 | D34: 0.52083333 | F34: =SUM(IF(C34="",0,IF(C34<TIME(8,0,0),TIME(8,0,0)-C34,0))) -> 0 | G34: =SUM( IF(OR(C34="",D34=""),0,MAX(0,IF(D34<C34,D34+1,D34)-MAX(C34,TIME(12,0,0))))) -> 0.020833333 | H34: =G34+F34 -> 0.020833333
A35: Ayudante | B35: Ricky Nelson Bonilla Villagra | C35: 0.33333333 | D35: 0.5625 | F35: =SUM(IF(C35="",0,IF(C35<TIME(8,0,0),TIME(8,0,0)-C35,0))) -> 0 | G35: =SUM( IF(OR(C35="",D35=""),0,MAX(0,IF(D35<C35,D35+1,D35)-MAX(C35,TIME(12,0,0))))) -> 0.0625 | H35: =G35+F35 -> 0.0625
A36: Ayudante | B36: Diego Manuel Potoy Vanegas | C36: 0.33333333 | D36: 0.5 | F36: =SUM(IF(C36="",0,IF(C36<TIME(8,0,0),TIME(8,0,0)-C36,0))) -> 0 | G36: =SUM( IF(OR(C36="",D36=""),0,MAX(0,IF(D36<C36,D36+1,D36)-MAX(C36,TIME(12,0,0))))) -> 0 | H36: =G36+F36 -> 0
A37: Ayudante | B37: Henry Alberto Arevalo Velasquez | C37: A CUENTAS DE HORAS ACUMULADAS
A38: Ayudante | B38: Magdiel Daniel Cruz Aleman | C38: 0.33333333 | D38: 0.5625 | F38: =SUM(IF(C38="",0,IF(C38<TIME(8,0,0),TIME(8,0,0)-C38,0))) -> 0 | G38: =SUM( IF(OR(C38="",D38=""),0,MAX(0,IF(D38<C38,D38+1,D38)-MAX(C38,TIME(12,0,0))))) -> 0.0625 | H38: =G38+F38 -> 0.0625
A39: Ayudante | B39: Carlos Jose Villavicencio Silva | C39: 0.33333333 | D39: 0.5625 | F39: =SUM(IF(C39="",0,IF(C39<TIME(8,0,0),TIME(8,0,0)-C39,0))) -> 0 | G39: =SUM( IF(OR(C39="",D39=""),0,MAX(0,IF(D39<C39,D39+1,D39)-MAX(C39,TIME(12,0,0))))) -> 0.0625 | H39: =G39+F39 -> 0.0625
A40: Ayudante | B40: Einer Eliasar Lopez Hernandez | C40: 0.33333333 | D40: 0.52083333 | F40: =SUM(IF(C40="",0,IF(C40<TIME(8,0,0),TIME(8,0,0)-C40,0))) -> 0 | G40: =SUM( IF(OR(C40="",D40=""),0,MAX(0,IF(D40<C40,D40+1,D40)-MAX(C40,TIME(12,0,0))))) -> 0.020833333 | H40: =G40+F40 -> 0.020833333
...

Sheet 04-09
B1: 0.33333333 | D1: REPORTE DE ASISTENCIA 04 DE SEPTIEMBRE DEL 2026.
A2: Cargo | B2: Nombre | C2: Entrada | D2: Salida | E2: Llegada Tarde | F2: HORAS ACUMULADAS ENTRADA | G2: HORAS ACUMULADAS SALIDAS | H2: Total | I2: Observaciones
A3: Supervisor | B3: David Castillo Martínez | C3: SUBSIDIO
A4: Admon. Bodega | B4: Lenin Amigo de Saul Mendoza Chavarria | C4: 0.33333333 | D4: 0.70833333 | F4: =SUM(IF(C4="",0,IF(C4<TIME(8,0,0),TIME(8,0,0)-C4,0))) -> 0 | G4: =SUM( IF(OR(C4="",D4=""),0,MAX(0,IF(D4<C4,D4+1,D4)-MAX(C4,TIME(17,0,0))))) -> 0 | H4: =G4+F4 -> 0
A5: Admon. Bodega | B5: Jose De Jesus Gaitan Lovo | C5: 0.34027778 | D5: 0.70833333 | F5: =SUM(IF(C5="",0,IF(C5<TIME(8,0,0),TIME(8,0,0)-C5,0))) -> 0 | G5: =SUM( IF(OR(C5="",D5=""),0,MAX(0,IF(D5<C5,D5+1,D5)-MAX(C5,TIME(17,0,0))))) -> 0 | H5: =G5+F5 -> 0 | I5: DEDUCIDO POR HORAS ACUMULADAS
A6: Admon. Bodega | B6: Fernando Mauricio Salazar | C6: 0.33333333 | D6: 0.70833333 | F6: =SUM(IF(C6="",0,IF(C6<TIME(8,0,0),TIME(8,0,0)-C6,0))) -> 0 | G6: =SUM( IF(OR(C6="",D6=""),0,MAX(0,IF(D6<C6,D6+1,D6)-MAX(C6,TIME(17,0,0))))) -> 0 | H6: =G6+F6 -> 0
A7: Admon. Bodega | B7: Elvis Anthony Martinez Hernandez | C7: 0.33333333 | D7: 0.70833333 | F7: =SUM(IF(C7="",0,IF(C7<TIME(8,0,0),TIME(8,0,0)-C7,0))) -> 0 | G7: =SUM( IF(OR(C7="",D7=""),0,MAX(0,IF(D7<C7,D7+1,D7)-MAX(C7,TIME(17,0,0))))) -> 0 | H7: =G7+F7 -> 0
A8: Conductor | B8: Denis Alberto Lopez Gonzaga | C8: 0.29166667 | D8: 0.8125 | F8: =SUM(IF(C8="",0,IF(C8<TIME(8,0,0),TIME(8,0,0)-C8,0))) -> 0.041666667 | G8: =SUM( IF(OR(C8="",D8=""),0,MAX(0,IF(D8<C8,D8+1,D8)-MAX(C8,TIME(17,0,0))))) -> 0.10416667 | H8: =G8+F8 -> 0.14583333
A9: Conductor | B9: Jose Gabriel Herrera | C9: 0.33333333 | D9: 0.70833333 | F9: =SUM(IF(C9="",0,IF(C9<TIME(8,0,0),TIME(8,0,0)-C9,0))) -> 0 | G9: =SUM( IF(OR(C9="",D9=""),0,MAX(0,IF(D9<C9,D9+1,D9)-MAX(C9,TIME(17,0,0))))) -> 0 | H9: =G9+F9 -> 0
A10: Conductor | B10: Francisco Valerio Altamirano | C10: 0.33333333 | D10: 0.72916667 | F10: =SUM(IF(C10="",0,IF(C10<TIME(8,0,0),TIME(8,0,0)-C10,0))) -> 0 | G10: =SUM( IF(OR(C10="",D10=""),0,MAX(0,IF(D10<C10,D10+1,D10)-MAX(C10,TIME(17,0,0))))) -> 0.020833333 | H10: =G10+F10 -> 0.020833333
A11: Conductor | B11: Manuel Salvador Centeno Salinas | C11: 0.33333333 | D11: 0.80555556 | F11: =SUM(IF(C11="",0,IF(C11<TIME(8,0,0),TIME(8,0,0)-C11,0))) -> 0 | G11: =SUM( IF(OR(C11="",D11=""),0,MAX(0,IF(D11<C11,D11+1,D11)-MAX(C11,TIME(17,0,0))))) -> 0.097222222 | H11: =G11+F11 -> 0.097222222
A12: Conductor | B12: Bayardo Benjamin Moran Lopez | C12: 0.33333333 | D12: 0.70833333 | F12: =SUM(IF(C12="",0,IF(C12<TIME(8,0,0),TIME(8,0,0)-C12,0))) -> 0 | G12: =SUM( IF(OR(C12="",D12=""),0,MAX(0,IF(D12<C12,D12+1,D12)-MAX(C12,TIME(17,0,0))))) -> 0 | H12: =G12+F12 -> 0
A13: Conductor | B13: Emerson Alberto Diaz Mendoza | C13: SUBSIDIO
A14: Conductor | B14: David Uriel Zamora Martinez | C14: 0.33333333 | D14: 0.70833333 | F14: =SUM(IF(C14="",0,IF(C14<TIME(8,0,0),TIME(8,0,0)-C14,0))) -> 0 | G14: =SUM( IF(OR(C14="",D14=""),0,MAX(0,IF(D14<C14,D14+1,D14)-MAX(C14,TIME(17,0,0))))) -> 0 | H14: =G14+F14 -> 0
A15: Conductor | B15: Jorge Luis Telleria | C15: 0.33333333 | D15: 0.70833333 | F15: =SUM(IF(C15="",0,IF(C15<TIME(8,0,0),TIME(8,0,0)-C15,0))) -> 0 | G15: =SUM( IF(OR(C15="",D15=""),0,MAX(0,IF(D15<C15,D15+1,D15)-MAX(C15,TIME(17,0,0))))) -> 0 | H15: =G15+F15 -> 0
A16: Conductor | B16: Alejandro Jose Castro Jarquin | C16: 0.33333333 | D16: 0.875 | F16: =SUM(IF(C16="",0,IF(C16<TIME(8,0,0),TIME(8,0,0)-C16,0))) -> 0 | G16: =SUM( IF(OR(C16="",D16=""),0,MAX(0,IF(D16<C16,D16+1,D16)-MAX(C16,TIME(17,0,0))))) -> 0.16666667 | H16: =G16+F16 -> 0.16666667
A17: Conductor | B17: Juan Francisco Narvaez Molina | C17: 0.33333333 | D17: 0.70833333 | F17: =SUM(IF(C17="",0,IF(C17<TIME(8,0,0),TIME(8,0,0)-C17,0))) -> 0 | G17: =SUM( IF(OR(C17="",D17=""),0,MAX(0,IF(D17<C17,D17+1,D17)-MAX(C17,TIME(17,0,0))))) -> 0 | H17: =G17+F17 -> 0
A18: Conductor | B18: Fernando Antonio Centeno Gaitan | C18: 0.33333333 | D18: 0.70833333 | F18: =SUM(IF(C18="",0,IF(C18<TIME(8,0,0),TIME(8,0,0)-C18,0))) -> 0 | G18: =SUM( IF(OR(C18="",D18=""),0,MAX(0,IF(D18<C18,D18+1,D18)-MAX(C18,TIME(17,0,0))))) -> 0 | H18: =G18+F18 -> 0
A19: Conductor | B19: Richard Antonio Carrion Alvarez | C19: VACACIONES
A20: Conductor | B20: Dietrich Rafael Bone Burgos | C20: VACACIONES
A21: Conductor | B21: Juan Abrahán Duran Tercero | C21: 0.32916667 | D21: 0.77083333 | F21: =SUM(IF(C21="",0,IF(C21<TIME(8,0,0),TIME(8,0,0)-C21,0))) -> 0.0041666667 | G21: =SUM( IF(OR(C21="",D21=""),0,MAX(0,IF(D21<C21,D21+1,D21)-MAX(C21,TIME(17,0,0))))) -> 0.0625 | H21: =G21+F21 -> 0.066666667
A22: Conductor | B22: Orlando José Ayerdis Barrios | C22: 0.33333333 | D22: 0.70833333 | F22: =SUM(IF(C22="",0,IF(C22<TIME(8,0,0),TIME(8,0,0)-C22,0))) -> 0 | G22: =SUM( IF(OR(C22="",D22=""),0,MAX(0,IF(D22<C22,D22+1,D22)-MAX(C22,TIME(17,0,0))))) -> 0 | H22: =G22+F22 -> 0
A23: Ayudante | B23: Walter Bernardino Aburto Maltez | C23: VACACIONES
A24: Ayudante | B24: Bismarck Antonio Perez Aburto | C24: 0.33333333 | D24: 0.70833333 | F24: =SUM(IF(C24="",0,IF(C24<TIME(8,0,0),TIME(8,0,0)-C24,0))) -> 0 | G24: =SUM( IF(OR(C24="",D24=""),0,MAX(0,IF(D24<C24,D24+1,D24)-MAX(C24,TIME(17,0,0))))) -> 0 | H24: =G24+F24 -> 0
A25: Ayudante | B25: Jose Ariel Espinoza Parrales | C25: 0.33333333 | D25: 0.87847222 | F25: =SUM(IF(C25="",0,IF(C25<TIME(8,0,0),TIME(8,0,0)-C25,0))) -> 0 | G25: =SUM( IF(OR(C25="",D25=""),0,MAX(0,IF(D25<C25,D25+1,D25)-MAX(C25,TIME(17,0,0))))) -> 0.17013889 | H25: =G25+F25 -> 0.17013889
A26: Ayudante | B26: Yaro de Jesus Castillo Muñoz | C26: 0.33333333 | D26: 0.70833333 | F26: =SUM(IF(C26="",0,IF(C26<TIME(8,0,0),TIME(8,0,0)-C26,0))) -> 0 | G26: =SUM( IF(OR(C26="",D26=""),0,MAX(0,IF(D26<C26,D26+1,D26)-MAX(C26,TIME(17,0,0))))) -> 0 | H26: =G26+F26 -> 0
A27: Ayudante | B27: Orlando De Jesus Ruiz Ramirez | C27: 0.33333333 | D27: 0.70833333 | F27: =SUM(IF(C27="",0,IF(C27<TIME(8,0,0),TIME(8,0,0)-C27,0))) -> 0 | G27: =SUM( IF(OR(C27="",D27=""),0,MAX(0,IF(D27<C27,D27+1,D27)-MAX(C27,TIME(17,0,0))))) -> 0 | H27: =G27+F27 -> 0
A28: Ayudante | B28: Roberto Jose Arauz Alvarado | C28: 0.33333333 | D28: 0.70833333 | F28: =SUM(IF(C28="",0,IF(C28<TIME(8,0,0),TIME(8,0,0)-C28,0))) -> 0 | G28: =SUM( IF(OR(C28="",D28=""),0,MAX(0,IF(D28<C28,D28+1,D28)-MAX(C28,TIME(17,0,0))))) -> 0 | H28: =G28+F28 -> 0
A29: Ayudante | B29: Luis Omar Campos Connolly | C29: 0.33333333 | D29: 0.70833333 | F29: =SUM(IF(C29="",0,IF(C29<TIME(8,0,0),TIME(8,0,0)-C29,0))) -> 0 | G29: =SUM( IF(OR(C29="",D29=""),0,MAX(0,IF(D29<C29,D29+1,D29)-MAX(C29,TIME(17,0,0))))) -> 0 | H29: =G29+F29 -> 0
A30: Ayudante | B30: Emilio Humberto Alegria Sanchez | C30: SUBSIDIO
A31: Ayudante | B31: Pablo Javier Berrios Sotelo | C31: 0.33333333 | D31: 0.70833333 | F31: =SUM(IF(C31="",0,IF(C31<TIME(8,0,0),TIME(8,0,0)-C31,0))) -> 0 | G31: =SUM( IF(OR(C31="",D31=""),0,MAX(0,IF(D31<C31,D31+1,D31)-MAX(C31,TIME(17,0,0))))) -> 0 | H31: =G31+F31 -> 0
A32: Ayudante | B32: Ramiro Isaac Solano Flores | C32: 0.33333333 | D32: 0.70833333 | F32: =SUM(IF(C32="",0,IF(C32<TIME(8,0,0),TIME(8,0,0)-C32,0))) -> 0 | G32: =SUM( IF(OR(C32="",D32=""),0,MAX(0,IF(D32<C32,D32+1,D32)-MAX(C32,TIME(17,0,0))))) -> 0 | H32: =G32+F32 -> 0
A33: Ayudante | B33: Reggie Sanders Rodriguez Tellez | C33: 0.33333333 | D33: 0.70833333 | F33: =SUM(IF(C33="",0,IF(C33<TIME(8,0,0),TIME(8,0,0)-C33,0))) -> 0 | G33: =SUM( IF(OR(C33="",D33=""),0,MAX(0,IF(D33<C33,D33+1,D33)-MAX(C33,TIME(17,0,0))))) -> 0 | H33: =G33+F33 -> 0
A34: Ayudante | B34: Engel Jose Brenes Aleman | C34: 0.33333333 | D34: 0.70833333 | F34: =SUM(IF(C34="",0,IF(C34<TIME(8,0,0),TIME(8,0,0)-C34,0))) -> 0 | G34: =SUM( IF(OR(C34="",D34=""),0,MAX(0,IF(D34<C34,D34+1,D34)-MAX(C34,TIME(17,0,0))))) -> 0 | H34: =G34+F34 -> 0
A35: Ayudante | B35: Ricky Nelson Bonilla Villagra | C35: 0.33333333 | D35: 0.70833333 | F35: =SUM(IF(C35="",0,IF(C35<TIME(8,0,0),TIME(8,0,0)-C35,0))) -> 0 | G35: =SUM( IF(OR(C35="",D35=""),0,MAX(0,IF(D35<C35,D35+1,D35)-MAX(C35,TIME(17,0,0))))) -> 0 | H35: =G35+F35 -> 0
A36: Ayudante | B36: Diego Manuel Potoy Vanegas | C36: 0.33333333 | D36: 0.66666667 | F36: =SUM(IF(C36="",0,IF(C36<TIME(8,0,0),TIME(8,0,0)-C36,0))) -> 0 | G36: =SUM( IF(OR(C36="",D36=""),0,MAX(0,IF(D36<C36,D36+1,D36)-MAX(C36,TIME(17,0,0))))) -> 0 | H36: =G36+F36 -> 0 | I36: DEDUCIDO POR HORAS ACUMULADAS
A37: Ayudante | B37: Henry Alberto Arevalo Velasquez | C37: 0.33333333 | D37: 0.87847222 | F37: =SUM(IF(C37="",0,IF(C37<TIME(8,0,0),TIME(8,0,0)-C37,0))) -> 0 | G37: =SUM( IF(OR(C37="",D37=""),0,MAX(0,IF(D37<C37,D37+1,D37)-MAX(C37,TIME(17,0,0))))) -> 0.17013889 | H37: =G37+F37 -> 0.17013889
A38: Ayudante | B38: Magdiel Daniel Cruz Aleman | C38: 0.33333333 | D38: 0.70833333 | F38: =SUM(IF(C38="",0,IF(C38<TIME(8,0,0),TIME(8,0,0)-C38,0))) -> 0 | G38: =SUM( IF(OR(C38="",D38=""),0,MAX(0,IF(D38<C38,D38+1,D38)-MAX(C38,TIME(17,0,0))))) -> 0 | H38: =G38+F38 -> 0
A39: Ayudante | B39: Carlos Jose Villavicencio Silva | C39: 0.33333333 | D39: 0.70833333 | F39: =SUM(IF(C39="",0,IF(C39<TIME(8,0,0),TIME(8,0,0)-C39,0))) -> 0 | G39: =SUM( IF(OR(C39="",D39=""),0,MAX(0,IF(D39<C39,D39+1,D39)-MAX(C39,TIME(17,0,0))))) -> 0 | H39: =G39+F39 -> 0
A40: Ayudante | B40: Einer Eliasar Lopez Hernandez | C40: 0.27777778 | D40: 0.70833333 | F40: =SUM(IF(C40="",0,IF(C40<TIME(8,0,0),TIME(8,0,0)-C40,0))) -> 0.055555556 | G40: =SUM( IF(OR(C40="",D40=""),0,MAX(0,IF(D40<C40,D40+1,D40)-MAX(C40,TIME(17,0,0))))) -> 0 | H40: =G40+F40 -> 0.055555556
...

Sheet 03-09
B1: 0.33333333 | D1: REPORTE DE ASISTENCIA 03 DE SEPTIEMBRE DEL 2026.
A2: Cargo | B2: Nombre | C2: Entrada | D2: Salida | E2: Llegada Tarde | F2: HORAS ACUMULADAS ENTRADA | G2: HORAS ACUMULADAS SALIDAS | H2: Total | I2: Observaciones
A3: Supervisor | B3: David Castillo Martínez | C3: SUBSIDIO
A4: Admon. Bodega | B4: Lenin Amigo de Saul Mendoza Chavarria | C4: 0.33333333 | D4: 0.72222222 | F4: =SUM(IF(C4="",0,IF(C4<TIME(8,0,0),TIME(8,0,0)-C4,0))) -> 0 | G4: =SUM( IF(OR(C4="",D4=""),0,MAX(0,IF(D4<C4,D4+1,D4)-MAX(C4,TIME(17,0,0))))) -> 0.013888889 | H4: =G4+F4 -> 0.013888889
A5: Admon. Bodega | B5: Jose De Jesus Gaitan Lovo | C5: 0.33333333 | D5: 0.72222222 | F5: =SUM(IF(C5="",0,IF(C5<TIME(8,0,0),TIME(8,0,0)-C5,0))) -> 0 | G5: =SUM( IF(OR(C5="",D5=""),0,MAX(0,IF(D5<C5,D5+1,D5)-MAX(C5,TIME(17,0,0))))) -> 0.013888889 | H5: =G5+F5 -> 0.013888889
A6: Admon. Bodega | B6: Fernando Mauricio Salazar | C6: 0.33333333 | D6: 0.72222222 | F6: =SUM(IF(C6="",0,IF(C6<TIME(8,0,0),TIME(8,0,0)-C6,0))) -> 0 | G6: =SUM( IF(OR(C6="",D6=""),0,MAX(0,IF(D6<C6,D6+1,D6)-MAX(C6,TIME(17,0,0))))) -> 0.013888889 | H6: =G6+F6 -> 0.013888889
A7: Admon. Bodega | B7: Elvis Anthony Martinez Hernandez | C7: 0.33333333 | D7: 0.72222222 | F7: =SUM(IF(C7="",0,IF(C7<TIME(8,0,0),TIME(8,0,0)-C7,0))) -> 0 | G7: =SUM( IF(OR(C7="",D7=""),0,MAX(0,IF(D7<C7,D7+1,D7)-MAX(C7,TIME(17,0,0))))) -> 0.013888889 | H7: =G7+F7 -> 0.013888889
A8: Admon. Bodega | B8: Sebastian Bautista Rostran Davila | C8: 0.33333333 | D8: 0.70833333 | F8: =SUM(IF(C8="",0,IF(C8<TIME(8,0,0),TIME(8,0,0)-C8,0))) -> 0 | G8: =SUM( IF(OR(C8="",D8=""),0,MAX(0,IF(D8<C8,D8+1,D8)-MAX(C8,TIME(17,0,0))))) -> 0 | H8: =G8+F8 -> 0
A9: Conductor | B9: Denis Alberto Lopez Gonzaga | C9: 0.33333333 | D9: 0.70833333 | F9: =SUM(IF(C9="",0,IF(C9<TIME(8,0,0),TIME(8,0,0)-C9,0))) -> 0 | G9: =SUM( IF(OR(C9="",D9=""),0,MAX(0,IF(D9<C9,D9+1,D9)-MAX(C9,TIME(17,0,0))))) -> 0 | H9: =G9+F9 -> 0
A10: Conductor | B10: Jose Gabriel Herrera | C10: 0.33333333 | D10: 0.70833333 | F10: =SUM(IF(C10="",0,IF(C10<TIME(8,0,0),TIME(8,0,0)-C10,0))) -> 0 | G10: =SUM( IF(OR(C10="",D10=""),0,MAX(0,IF(D10<C10,D10+1,D10)-MAX(C10,TIME(17,0,0))))) -> 0 | H10: =G10+F10 -> 0
A11: Conductor | B11: Francisco Valerio Altamirano | C11: 0.33333333 | D11: 0.70833333 | F11: =SUM(IF(C11="",0,IF(C11<TIME(8,0,0),TIME(8,0,0)-C11,0))) -> 0 | G11: =SUM( IF(OR(C11="",D11=""),0,MAX(0,IF(D11<C11,D11+1,D11)-MAX(C11,TIME(17,0,0))))) -> 0 | H11: =G11+F11 -> 0
A12: Conductor | B12: Manuel Salvador Centeno Salinas | C12: 0.33333333 | D12: 0.70833333 | F12: =SUM(IF(C12="",0,IF(C12<TIME(8,0,0),TIME(8,0,0)-C12,0))) -> 0 | G12: =SUM( IF(OR(C12="",D12=""),0,MAX(0,IF(D12<C12,D12+1,D12)-MAX(C12,TIME(17,0,0))))) -> 0 | H12: =G12+F12 -> 0
A13: Conductor | B13: Bayardo Benjamin Moran Lopez | C13: 0.33333333 | D13: 0.72916667 | F13: =SUM(IF(C13="",0,IF(C13<TIME(8,0,0),TIME(8,0,0)-C13,0))) -> 0 | G13: =SUM( IF(OR(C13="",D13=""),0,MAX(0,IF(D13<C13,D13+1,D13)-MAX(C13,TIME(17,0,0))))) -> 0.020833333 | H13: =G13+F13 -> 0.020833333
A14: Conductor | B14: Emerson Alberto Diaz Mendoza | C14: 0.33333333 | D14: 0.70833333 | F14: =SUM(IF(C14="",0,IF(C14<TIME(8,0,0),TIME(8,0,0)-C14,0))) -> 0 | G14: =SUM( IF(OR(C14="",D14=""),0,MAX(0,IF(D14<C14,D14+1,D14)-MAX(C14,TIME(17,0,0))))) -> 0 | H14: =G14+F14 -> 0
A15: Conductor | B15: David Uriel Zamora Martinez | C15: 0.33333333 | D15: 0.70833333 | F15: =SUM(IF(C15="",0,IF(C15<TIME(8,0,0),TIME(8,0,0)-C15,0))) -> 0 | G15: =SUM( IF(OR(C15="",D15=""),0,MAX(0,IF(D15<C15,D15+1,D15)-MAX(C15,TIME(17,0,0))))) -> 0 | H15: =G15+F15 -> 0
... A19: Conductor | B19: Fernando Antonio Centeno Gaitan | C19: 0.33333333 | D19: 0.86597222 | F19: =SUM(IF(C19="",0,IF(C19<TIME(8,0,0),TIME(8,0,0)-C19,0))) -> 0 | G19: =SUM( IF(OR(C19="",D19=""),0,MAX(0,IF(D19<C19,D19+1,D19)-MAX(C19,TIME(17,0,0))))) -> 0.15763889 | H19: =G19+F19 -> 0.15763889
A20: Conductor | B20: Richard Antonio Carrion Alvarez | C20: VACACIONES
A21: Conductor | B21: Dietrich Rafael Bone Burgos | C21: VACACIONES
A22: Conductor | B22: Juan Abrahán Duran Tercero | C22: 0.33333333 | D22: 0.72222222 | F22: =SUM(IF(C22="",0,IF(C22<TIME(8,0,0),TIME(8,0,0)-C22,0))) -> 0 | G22: =SUM( IF(OR(C22="",D22=""),0,MAX(0,IF(D22<C22,D22+1,D22)-MAX(C22,TIME(17,0,0))))) -> 0.013888889 | H22: =G22+F22 -> 0.013888889
A23: Conductor | B23: Orlando José Ayerdis Barrios | C23: 0.33333333 | D23: 0.70833333 | F23: =SUM(IF(C23="",0,IF(C23<TIME(8,0,0),TIME(8,0,0)-C23,0))) -> 0 | G23: =SUM( IF(OR(C23="",D23=""),0,MAX(0,IF(D23<C23,D23+1,D23)-MAX(C23,TIME(17,0,0))))) -> 0 | H23: =G23+F23 -> 0
A24: Ayudante | B24: Walter Bernardino Aburto Maltez | C24: VACACIONES
A25: Ayudante | B25: Bismarck Antonio Perez Aburto | C25: VACACIONES
A26: Ayudante | B26: Jose Ariel Espinoza Parrales | C26: 0.33333333 | D26: 0.72222222 | F26: =SUM(IF(C26="",0,IF(C26<TIME(8,0,0),TIME(8,0,0)-C26,0))) -> 0 | G26: =SUM( IF(OR(C26="",D26=""),0,MAX(0,IF(D26<C26,D26+1,D26)-MAX(C26,TIME(17,0,0))))) -> 0.013888889 | H26: =G26+F26 -> 0.013888889
A27: Ayudante | B27: Yaro de Jesus Castillo Muñoz | C27: 0.33333333 | D27: 0.72222222 | F27: =SUM(IF(C27="",0,IF(C27<TIME(8,0,0),TIME(8,0,0)-C27,0))) -> 0 | G27: =SUM( IF(OR(C27="",D27=""),0,MAX(0,IF(D27<C27,D27+1,D27)-MAX(C27,TIME(17,0,0))))) -> 0.013888889 | H27: =G27+F27 -> 0.013888889
A28: Ayudante | B28: Orlando De Jesus Ruiz Ramirez | C28: 0.33333333 | D28: 0.72222222 | F28: =SUM(IF(C28="",0,IF(C28<TIME(8,0,0),TIME(8,0,0)-C28,0))) -> 0 | G28: =SUM( IF(OR(C28="",D28=""),0,MAX(0,IF(D28<C28,D28+1,D28)-MAX(C28,TIME(17,0,0))))) -> 0.013888889 | H28: =G28+F28 -> 0.013888889
A29: Ayudante | B29: Roberto Jose Arauz Alvarado | C29: 0.33333333 | D29: 0.70833333 | F29: =SUM(IF(C29="",0,IF(C29<TIME(8,0,0),TIME(8,0,0)-C29,0))) -> 0 | G29: =SUM( IF(OR(C29="",D29=""),0,MAX(0,IF(D29<C29,D29+1,D29)-MAX(C29,TIME(17,0,0))))) -> 0 | H29: =G29+F29 -> 0
A30: Ayudante | B30: Luis Omar Campos Connolly | C30: 0.33333333 | D30: 0.70833333 | F30: =SUM(IF(C30="",0,IF(C30<TIME(8,0,0),TIME(8,0,0)-C30,0))) -> 0 | G30: =SUM( IF(OR(C30="",D30=""),0,MAX(0,IF(D30<C30,D30+1,D30)-MAX(C30,TIME(17,0,0))))) -> 0 | H30: =G30+F30 -> 0
A31: Ayudante | B31: Emilio Humberto Alegria Sanchez | C31: SUBSIDIO
A32: Ayudante | B32: Pablo Javier Berrios Sotelo | C32: 0.36458333 | D32: 0.86597222 | F32: =SUM(IF(C32="",0,IF(C32<TIME(8,0,0),TIME(8,0,0)-C32,0))) -> 0 | G32: =SUM( IF(OR(C32="",D32=""),0,MAX(0,IF(D32<C32,D32+1,D32)-MAX(C32,TIME(17,0,0))))) -> 0.15763889 | H32: =G32+F32 -> 0.15763889 | I32: DEDUCIDO POR HORAS ACUMULADAS
A33: Ayudante | B33: Ramiro Isaac Solano Flores | C33: 0.33333333 | D33: 0.72222222 | F33: =SUM(IF(C33="",0,IF(C33<TIME(8,0,0),TIME(8,0,0)-C33,0))) -> 0 | G33: =SUM( IF(OR(C33="",D33=""),0,MAX(0,IF(D33<C33,D33+1,D33)-MAX(C33,TIME(17,0,0))))) -> 0.013888889 | H33: =G33+F33 -> 0.013888889
A34: Ayudante | B34: Reggie Sanders Rodriguez Tellez | C34: 0.33333333 | D34: 0.70833333 | F34: =SUM(IF(C34="",0,IF(C34<TIME(8,0,0),TIME(8,0,0)-C34,0))) -> 0 | G34: =SUM( IF(OR(C34="",D34=""),0,MAX(0,IF(D34<C34,D34+1,D34)-MAX(C34,TIME(17,0,0))))) -> 0 | H34: =G34+F34 -> 0
A35: Ayudante | B35: Engel Jose Brenes Aleman | C35: 0.33333333 | D35: 0.70833333 | F35: =SUM(IF(C35="",0,IF(C35<TIME(8,0,0),TIME(8,0,0)-C35,0))) -> 0 | G35: =SUM( IF(OR(C35="",D35=""),0,MAX(0,IF(D35<C35,D35+1,D35)-MAX(C35,TIME(17,0,0))))) -> 0 | H35: =G35+F35 -> 0
A36: Ayudante | B36: Ricky Nelson Bonilla Villagra | C36: 0.33333333 | D36: 0.72222222 | F36: =SUM(IF(C36="",0,IF(C36<TIME(8,0,0),TIME(8,0,0)-C36,0))) -> 0 | G36: =SUM( IF(OR(C36="",D36=""),0,MAX(0,IF(D36<C36,D36+1,D36)-MAX(C36,TIME(17,0,0))))) -> 0.013888889 | H36: =G36+F36 -> 0.013888889
A37: Ayudante | B37: Diego Manuel Potoy Vanegas | C37: 0.33333333 | D37: 0.70833333 | F37: =SUM(IF(C37="",0,IF(C37<TIME(8,0,0),TIME(8,0,0)-C37,0))) -> 0 | G37: =SUM( IF(OR(C37="",D37=""),0,MAX(0,IF(D37<C37,D37+1,D37)-MAX(C37,TIME(17,0,0))))) -> 0 | H37: =G37+F37 -> 0
A38: Ayudante | B38: Henry Alberto Arevalo Velasquez | C38: 0.33333333 | D38: 0.70833333 | F38: =SUM(IF(C38="",0,IF(C38<TIME(8,0,0),TIME(8,0,0)-C38,0))) -> 0 | G38: =SUM( IF(OR(C38="",D38=""),0,MAX(0,IF(D38<C38,D38+1,D38)-MAX(C38,TIME(17,0,0))))) -> 0 | H38: =G38+F38 -> 0
A39: Ayudante | B39: Magdiel Daniel Cruz Aleman | C39: 0.33333333 | D39: 0.70833333 | F39: =SUM(IF(C39="",0,IF(C39<TIME(8,0,0),TIME(8,0,0)-C39,0))) -> 0 | G39: =SUM( IF(OR(C39="",D39=""),0,MAX(0,IF(D39<C39,D39+1,D39)-MAX(C39,TIME(17,0,0))))) -> 0 | H39: =G39+F39 -> 0
A40: Ayudante | B40: Carlos Jose Villavicencio Silva | C40: 0.33333333 | D40: 0.70833333 | F40: =SUM(IF(C40="",0,IF(C40<TIME(8,0,0),TIME(8,0,0)-C40,0))) -> 0 | G40: =SUM( IF(OR(C40="",D40=""),0,MAX(0,IF(D40<C40,D40+1,D40)-MAX(C40,TIME(17,0,0))))) -> 0 | H40: =G40+F40 -> 0
A41: Ayudante | B41: Einer Eliasar Lopez Hernandez | C41: 0.33333333 | D41: 0.72222222 | F41: =SUM(IF(C41="",0,IF(C41<TIME(8,0,0),TIME(8,0,0)-C41,0))) -> 0 | G41: =SUM( IF(OR(C41="",D41=""),0,MAX(0,IF(D41<C41,D41+1,D41)-MAX(C41,TIME(17,0,0))))) -> 0.013888889 | H41: =G41+F41 -> 0.013888889
A42: Ayudante | B42: Walter Roberto Vasquez Ramos | C42: 0.33333333 | D42: 0.70833333 | F42: =SUM(IF(C42="",0,IF(C42<TIME(8,0,0),TIME(8,0,0)-C42,0))) -> 0 | G42: =SUM( IF(OR(C42="",D42=""),0,MAX(0,IF(D42<C42,D42+1,D42)-MAX(C42,TIME(17,0,0))))) -> 0 | H42: =G42+F42 -> 0
A43: Ayudante | B43: Joel Alfonso Rocha Guzman | C43: 0.33333333 | D43: 0.70833333 | F43: =SUM(IF(C43="",0,IF(C43<TIME(8,0,0),TIME(8,0,0)-C43,0))) -> 0 | G43: =SUM( IF(OR(C43="",D43=""),0,MAX(0,IF(D43<C43,D43+1,D43)-MAX(C43,TIME(17,0,0))))) -> 0 | H43: =G43+F43 -> 0
...

Sheet 02-09
B1: 0.33333333 | D1: REPORTE DE ASISTENCIA 02 DE SEPTIEMBRE DEL 2026.
A2: Cargo | B2: Nombre | C2: Entrada | D2: Salida | E2: Llegada Tarde | F2: HORAS ACUMULADAS ENTRADA | G2: HORAS ACUMULADAS SALIDAS | H2: Total | I2: Observaciones
A3: Supervisor | B3: David Castillo Martínez | C3: SUBSIDIO
A4: Admon. Bodega | B4: Lenin Amigo de Saul Mendoza Chavarria | C4: 0.46041667 | D4: 0.72916667 | F4: =SUM(IF(C4="",0,IF(C4<TIME(8,0,0),TIME(8,0,0)-C4,0))) -> 0 | G4: =SUM( IF(OR(C4="",D4=""),0,MAX(0,IF(D4<C4,D4+1,D4)-MAX(C4,TIME(17,0,0))))) -> 0.020833333 | H4: =G4+F4 -> 0.020833333 | I4: Clinico
A5: Admon. Bodega | B5: Jose De Jesus Gaitan Lovo | C5: 0.33333333 | D5: 0.72916667 | F5: =SUM(IF(C5="",0,IF(C5<TIME(8,0,0),TIME(8,0,0)-C5,0))) -> 0 | G5: =SUM( IF(OR(C5="",D5=""),0,MAX(0,IF(D5<C5,D5+1,D5)-MAX(C5,TIME(17,0,0))))) -> 0.020833333 | H5: =G5+F5 -> 0.020833333
A6: Admon. Bodega | B6: Fernando Mauricio Salazar | C6: 0.33333333 | D6: 0.72916667 | F6: =SUM(IF(C6="",0,IF(C6<TIME(8,0,0),TIME(8,0,0)-C6,0))) -> 0 | G6: =SUM( IF(OR(C6="",D6=""),0,MAX(0,IF(D6<C6,D6+1,D6)-MAX(C6,TIME(17,0,0))))) -> 0.020833333 | H6: =G6+F6 -> 0.020833333
A7: Admon. Bodega | B7: Elvis Anthony Martinez Hernandez | C7: 0.33333333 | D7: 0.71527778 | F7: =SUM(IF(C7="",0,IF(C7<TIME(8,0,0),TIME(8,0,0)-C7,0))) -> 0 | G7: =SUM( IF(OR(C7="",D7=""),0,MAX(0,IF(D7<C7,D7+1,D7)-MAX(C7,TIME(17,0,0))))) -> 0.0069444444 | H7: =G7+F7 -> 0.0069444444
A8: Admon. Bodega | B8: Sebastian Bautista Rostran Davila | C8: 0.33333333 | D8: 0.70833333 | F8: =SUM(IF(C8="",0,IF(C8<TIME(8,0,0),TIME(8,0,0)-C8,0))) -> 0 | G8: =SUM( IF(OR(C8="",D8=""),0,MAX(0,IF(D8<C8,D8+1,D8)-MAX(C8,TIME(17,0,0))))) -> 0 | H8: =G8+F8 -> 0
A9: Conductor | B9: Denis Alberto Lopez Gonzaga | C9: 0.33333333 | D9: 0.78194444 | F9: =SUM(IF(C9="",0,IF(C9<TIME(8,0,0),TIME(8,0,0)-C9,0))) -> 0 | G9: =SUM( IF(OR(C9="",D9=""),0,MAX(0,IF(D9<C9,D9+1,D9)-MAX(C9,TIME(17,0,0))))) -> 0.073611111 | H9: =G9+F9 -> 0.073611111
A10: Conductor | B10: Jose Gabriel Herrera | C10: 0.33333333 | D10: 0.71527778 | F10: =SUM(IF(C10="",0,IF(C10<TIME(8,0,0),TIME(8,0,0)-C10,0))) -> 0 | G10: =SUM( IF(OR(C10="",D10=""),0,MAX(0,IF(D10<C10,D10+1,D10)-MAX(C10,TIME(17,0,0))))) -> 0.0069444444 | H10: =G10+F10 -> 0.0069444444
A11: Conductor | B11: Francisco Valerio Altamirano | C11: 0.33333333 | D11: 0.72916667 | F11: =SUM(IF(C11="",0,IF(C11<TIME(8,0,0),TIME(8,0,0)-C11,0))) -> 0 | G11: =SUM( IF(OR(C11="",D11=""),0,MAX(0,IF(D11<C11,D11+1,D11)-MAX(C11,TIME(17,0,0))))) -> 0.020833333 | H11: =G11+F11 -> 0.020833333
A12: Conductor | B12: Manuel Salvador Centeno Salinas | C12: 0.33333333 | D12: 0.70833333 | F12: =SUM(IF(C12="",0,IF(C12<TIME(8,0,0),TIME(8,0,0)-C12,0))) -> 0 | G12: =SUM( IF(OR(C12="",D12=""),0,MAX(0,IF(D12<C12,D12+1,D12)-MAX(C12,TIME(17,0,0))))) -> 0 | H12: =G12+F12 -> 0
A13: Conductor | B13: Bayardo Benjamin Moran Lopez | C13: 0.33333333 | D13: 0.79861111 | F13: =SUM(IF(C13="",0,IF(C13<TIME(8,0,0),TIME(8,0,0)-C13,0))) -> 0 | G13: =SUM( IF(OR(C13="",D13=""),0,MAX(0,IF(D13<C13,D13+1,D13)-MAX(C13,TIME(17,0,0))))) -> 0.090277778 | H13: =G13+F13 -> 0.090277778
A14: Conductor | B14: Emerson Alberto Diaz Mendoza | C14: 0.33333333 | D14: 0.75 | F14: =SUM(IF(C14="",0,IF(C14<TIME(8,0,0),TIME(8,0,0)-C14,0))) -> 0 | G14: =SUM( IF(OR(C14="",D14=""),0,MAX(0,IF(D14<C14,D14+1,D14)-MAX(C14,TIME(17,0,0))))) -> 0.041666667 | H14: =G14+F14 -> 0.041666667
A15: Conductor | B15: David Uriel Zamora Martinez | C15: 0.33333333 | D15: 0.70833333 | F15: =SUM(IF(C15="",0,IF(C15<TIME(8,0,0),TIME(8,0,0)-C15,0))) -> 0 | G15: =SUM( IF(OR(C15="",D15=""),0,MAX(0,IF(D15<C15,D15+1,D15)-MAX(C15,TIME(17,0,0))))) -> 0 | H15: =G15+F15 -> 0
A16: Conductor | B16: Jorge Luis Telleria | C16: 0.33333333 | D16: 0.71527778 | F16: =SUM(IF(C16="",0,IF(C16<TIME(8,0,0),TIME(8,0,0)-C16,0))) -> 0 | G16: =SUM( IF(OR(C16="",D16=""),0,MAX(0,IF(D16<C16,D16+1,D16)-MAX(C16,TIME(17,0,0))))) -> 0.0069444444 | H16: =G16+F16 -> 0.0069444444
A17: Conductor | B17: Alejandro Jose Castro Jarquin | C17: A CUENTAS DE HORAS ACUMULADAS
A18: Conductor | B18: Juan Francisco Narvaez Molina | C18: 0.33333333 | D18: 0.72916667 | F18: =SUM(IF(C18="",0,IF(C18<TIME(8,0,0),TIME(8,0,0)-C18,0))) -> 0 | G18: =SUM( IF(OR(C18="",D18=""),0,MAX(0,IF(D18<C18,D18+1,D18)-MAX(C18,TIME(17,0,0))))) -> 0.020833333 | H18: =G18+F18 -> 0.020833333
A19: Conductor | B19: Fernando Antonio Centeno Gaitan | C19: 0.33333333 | D19: 0.70833333 | F19: =SUM(IF(C19="",0,IF(C19<TIME(8,0,0),TIME(8,0,0)-C19,0))) -> 0 | G19: =SUM( IF(OR(C19="",D19=""),0,MAX(0,IF(D19<C19,D19+1,D19)-MAX(C19,TIME(17,0,0))))) -> 0 | H19: =G19+F19 -> 0
A20: Conductor | B20: Richard Antonio Carrion Alvarez | C20: VACACIONES
A21: Conductor | B21: Dietrich Rafael Bone Burgos | C21: VACACIONES
A22: Conductor | B22: Juan Abrahán Duran Tercero | C22: 0.35 | D22: 0.70833333 | F22: =SUM(IF(C22="",0,IF(C22<TIME(8,0,0),TIME(8,0,0)-C22,0))) -> 0 | G22: =SUM( IF(OR(C22="",D22=""),0,MAX(0,IF(D22<C22,D22+1,D22)-MAX(C22,TIME(17,0,0))))) -> 0 | H22: =G22+F22 -> 0 | I22: DEDUCIDO POR HORAS ACUMULADAS
A23: Conductor | B23: Orlando José Ayerdis Barrios | C23: 0.33333333 | D23: 0.70833333 | F23: =SUM(IF(C23="",0,IF(C23<TIME(8,0,0),TIME(8,0,0)-C23,0))) -> 0 | G23: =SUM( IF(OR(C23="",D23=""),0,MAX(0,IF(D23<C23,D23+1,D23)-MAX(C23,TIME(17,0,0))))) -> 0 | H23: =G23+F23 -> 0
A24: Ayudante | B24: Walter Bernardino Aburto Maltez | C24: 0.33333333 | D24: 0.71527778 | F24: =SUM(IF(C24="",0,IF(C24<TIME(8,0,0),TIME(8,0,0)-C24,0))) -> 0 | G24: =SUM( IF(OR(C24="",D24=""),0,MAX(0,IF(D24<C24,D24+1,D24)-MAX(C24,TIME(17,0,0))))) -> 0.0069444444 | H24: =G24+F24 -> 0.0069444444
A25: Ayudante | B25: Bismarck Antonio Perez Aburto | C25: 0.33333333 | D25: 0.72916667 | F25: =SUM(IF(C25="",0,IF(C25<TIME(8,0,0),TIME(8,0,0)-C25,0))) -> 0 | G25: =SUM( IF(OR(C25="",D25=""),0,MAX(0,IF(D25<C25,D25+1,D25)-MAX(C25,TIME(17,0,0))))) -> 0.020833333 | H25: =G25+F25 -> 0.020833333
A26: Ayudante | B26: Jose Ariel Espinoza Parrales | C26: 0.33333333 | D26: 0.72916667 | F26: =SUM(IF(C26="",0,IF(C26<TIME(8,0,0),TIME(8,0,0)-C26,0))) -> 0 | G26: =SUM( IF(OR(C26="",D26=""),0,MAX(0,IF(D26<C26,D26+1,D26)-MAX(C26,TIME(17,0,0))))) -> 0.020833333 | H26: =G26+F26 -> 0.020833333
